Workbook

Sheet spread
A1: Date | B1: US 10 Year Yield | C1: US 30 Year Yield | D1: China 10 Year Yield | E1: US Minus China 10Y Spread | F1: BTC Spot Price | G1: US 2 Year Yield | H1: China 2 Year Yield | I1: 2s10s | J1: DXY | K1: BTC ReT | L1: Japan 10Y | M1: Japan 2Y | N1: SPX | O1: NDX | P1: US 5 Year Yield | Q1: 5s30s | R1: 10Y US Minus 10Y Japan
A2: 42005 | E2: =IF(AND(ISNUMBER(B2), ISNUMBER(D2)), B2-D2, "") | F2: 314.49 | I2: =IF(AND(ISNUMBER(B2), ISNUMBER(G2)), B2-G2, "") | J2: 90.276 | Q2: =IF(AND(ISNUMBER(C2), ISNUMBER(P2)), C2-P2, "") | R2: =IF(AND(ISNUMBER(B2), ISNUMBER(L2)), B2-L2, "")
A3: 42006 | B3: 2.1105 | C3: 2.688 | E3: =IF(AND(ISNUMBER(B3), ISNUMBER(D3)), B3-D3, "") | F3: 314.73 | G3: 0.6647 | I3: =IF(AND(ISNUMBER(B3), ISNUMBER(G3)), B3-G3, "") -> 1.4458 | J3: 91.08 | K3: =F3/F2-1 -> 0.00076314032 | N3: 2058.2 | O3: 4230.2402 | P3: 1.607 | Q3: =IF(AND(ISNUMBER(C3), ISNUMBER(P3)), C3-P3, "") -> 1.081 | R3: =IF(AND(ISNUMBER(B3), ISNUMBER(L3)), B3-L3, "")
A4: 42008 | E4: =IF(AND(ISNUMBER(B4), ISNUMBER(D4)), B4-D4, "") | F4: 266.26 | I4: =IF(AND(ISNUMBER(B4), ISNUMBER(G4)), B4-G4, "") | K4: =F4/F3-1 -> -0.15400502 | Q4: =IF(AND(ISNUMBER(C4), ISNUMBER(P4)), C4-P4, "") | R4: =IF(AND(ISNUMBER(B4), ISNUMBER(L4)), B4-L4, "")
A5: 42009 | B5: 2.032 | C5: 2.5987 | D5: 3.65 | E5: =IF(AND(ISNUMBER(B5), ISNUMBER(D5)), B5-D5, "") -> -1.618 | F5: 270.93 | G5: 0.6568 | H5: 3.34 | I5: =IF(AND(ISNUMBER(B5), ISNUMBER(G5)), B5-G5, "") -> 1.3752 | J5: 91.378 | K5: =F5/F4-1 -> 0.017539247 | L5: 0.32 | M5: -0.025 | N5: 2020.58 | O5: 4160.96 | P5: 1.5645 | Q5: =IF(AND(ISNUMBER(C5), ISNUMBER(P5)), C5-P5, "") -> 1.0342 | R5: =IF(AND(ISNUMBER(B5), ISNUMBER(L5)), B5-L5, "") -> 1.712
A6: 42010 | B6: 1.9402 | C6: 2.5023 | D6: 3.64 | E6: =IF(AND(ISNUMBER(B6), ISNUMBER(D6)), B6-D6, "") -> -1.6998 | F6: 286.41 | G6: 0.625 | H6: 3.33 | I6: =IF(AND(ISNUMBER(B6), ISNUMBER(G6)), B6-G6, "") -> 1.3152 | J6: 91.499 | K6: =F6/F5-1 -> 0.05713653 | L6: 0.288 | M6: -0.026 | N6: 2002.61 | O6: 4110.8301 | P6: 1.478 | Q6: =IF(AND(ISNUMBER(C6), ISNUMBER(P6)), C6-P6, "") -> 1.0243 | R6: =IF(AND(ISNUMBER(B6), ISNUMBER(L6)), B6-L6, "") -> 1.6522
A7: 42011 | B7: 1.9677 | C7: 2.5289 | D7: 3.65 | E7: =IF(AND(ISNUMBER(B7), ISNUMBER(D7)), B7-D7, "") -> -1.6823 | F7: 296.13 | G7: 0.6091 | H7: 3.3 | I7: =IF(AND(ISNUMBER(B7), ISNUMBER(G7)), B7-G7, "") -> 1.3586 | J7: 91.89 | K7: =F7/F6-1 -> 0.033937363 | L7: 0.296 | M7: -0.026 | N7: 2025.9 | O7: 4160 | P7: 1.4779 | Q7: =IF(AND(ISNUMBER(C7), ISNUMBER(P7)), C7-P7, "") -> 1.051 | R7: =IF(AND(ISNUMBER(B7), ISNUMBER(L7)), B7-L7, "") -> 1.6717
A8: 42012 | B8: 2.0179 | C8: 2.5993 | E8: =IF(AND(ISNUMBER(B8), ISNUMBER(D8)), B8-D8, "") | F8: 293.83 | G8: 0.6051 | I8: =IF(AND(ISNUMBER(B8), ISNUMBER(G8)), B8-G8, "") -> 1.4128 | J8: 92.368 | K8: =F8/F7-1 -> -0.0077668591 | L8: 0.288 | M8: -0.027 | N8: 2062.14 | O8: 4240.5498 | P8: 1.4909 | Q8: =IF(AND(ISNUMBER(C8), ISNUMBER(P8)), C8-P8, "") -> 1.1084 | R8: =IF(AND(ISNUMBER(B8), ISNUMBER(L8)), B8-L8, "") -> 1.7299
A9: 42013 | B9: 1.9449 | C9: 2.5281 | E9: =IF(AND(ISNUMBER(B9), ISNUMBER(D9)), B9-D9, "") | F9: 289.81 | G9: 0.561 | I9: =IF(AND(ISNUMBER(B9), ISNUMBER(G9)), B9-G9, "") -> 1.3839 | J9: 91.935 | K9: =F9/F8-1 -> -0.01368138 | L9: 0.269 | M9: -0.036 | N9: 2044.81 | O9: 4213.2798 | P9: 1.419 | Q9: =IF(AND(ISNUMBER(C9), ISNUMBER(P9)), C9-P9, "") -> 1.1091 | R9: =IF(AND(ISNUMBER(B9), ISNUMBER(L9)), B9-L9, "") -> 1.6759
A10: 42015 | E10: =IF(AND(ISNUMBER(B10), ISNUMBER(D10)), B10-D10, "") | F10: 268.12 | I10: =IF(AND(ISNUMBER(B10), ISNUMBER(G10)), B10-G10, "") | K10: =F10/F9-1 -> -0.074842138 | Q10: =IF(AND(ISNUMBER(C10), ISNUMBER(P10)), C10-P10, "") | R10: =IF(AND(ISNUMBER(B10), ISNUMBER(L10)), B10-L10, "")
A11: 42016 | B11: 1.907 | C11: 2.4965 | D11: 3.65 | E11: =IF(AND(ISNUMBER(B11), ISNUMBER(D11)), B11-D11, "") -> -1.743 | F11: 270.65 | G11: 0.5449 | H11: 3.29 | I11: =IF(AND(ISNUMBER(B11), ISNUMBER(G11)), B11-G11, "") -> 1.3621 | J11: 91.983 | K11: =F11/F10-1 -> 0.0094360734 | N11: 2028.26 | O11: 4169.9702 | P11: 1.3799 | Q11: =IF(AND(ISNUMBER(C11), ISNUMBER(P11)), C11-P11, "") -> 1.1166 | R11: =IF(AND(ISNUMBER(B11), ISNUMBER(L11)), B11-L11, "")
A12: 42017 | B12: 1.9 | C12: 2.4992 | E12: =IF(AND(ISNUMBER(B12), ISNUMBER(D12)), B12-D12, "") | F12: 236.05 | G12: 0.5388 | I12: =IF(AND(ISNUMBER(B12), ISNUMBER(G12)), B12-G12, "") -> 1.3612 | J12: 92.31 | K12: =F12/F11-1 -> -0.12784038 | L12: 0.258 | M12: -0.03 | N12: 2023.03 | O12: 4166.2002 | P12: 1.3684 | Q12: =IF(AND(ISNUMBER(C12), ISNUMBER(P12)), C12-P12, "") -> 1.1308 | R12: =IF(AND(ISNUMBER(B12), ISNUMBER(L12)), B12-L12, "") -> 1.642
A13: 42018 | B13: 1.8553 | C13: 2.4685 | E13: =IF(AND(ISNUMBER(B13), ISNUMBER(D13)), B13-D13, "") | F13: 183.07 | G13: 0.5006 | I13: =IF(AND(ISNUMBER(B13), ISNUMBER(G13)), B13-G13, "") -> 1.3547 | J13: 92.161 | K13: =F13/F12-1 -> -0.22444397 | L13: 0.249 | M13: -0.03 | N13: 2011.27 | O13: 4145.8398 | P13: 1.3196 | Q13: =IF(AND(ISNUMBER(C13), ISNUMBER(P13)), C13-P13, "") -> 1.1489 | R13: =IF(AND(ISNUMBER(B13), ISNUMBER(L13)), B13-L13, "") -> 1.6063
A14: 42019 | B14: 1.7149 | C14: 2.3677 | D14: 3.56 | E14: =IF(AND(ISNUMBER(B14), ISNUMBER(D14)), B14-D14, "") -> -1.8451 | F14: 206.68 | G14: 0.4122 | H14: 3.24 | I14: =IF(AND(ISNUMBER(B14), ISNUMBER(G14)), B14-G14, "") -> 1.3027 | J14: 92.352 | K14: =F14/F13-1 -> 0.12896706 | L14: 0.248 | M14: -0.029 | N14: 1992.67 | O14: 4089.6499 | P14: 1.1613 | Q14: =IF(AND(ISNUMBER(C14), ISNUMBER(P14)), C14-P14, "") -> 1.2064 | R14: =IF(AND(ISNUMBER(B14), ISNUMBER(L14)), B14-L14, "") -> 1.4669
A15: 42020 | B15: 1.8368 | C15: 2.4531 | D15: 3.57 | E15: =IF(AND(ISNUMBER(B15), ISNUMBER(D15)), B15-D15, "") -> -1.7332 | F15: 208.34 | G15: 0.4835 | H15: 3.23 | I15: =IF(AND(ISNUMBER(B15), ISNUMBER(G15)), B15-G15, "") -> 1.3533 | J15: 92.52 | K15: =F15/F14-1 -> 0.0080317399 | L15: 0.237 | M15: -0.03 | N15: 2019.42 | O15: 4142.1401 | P15: 1.3026 | Q15: =IF(AND(ISNUMBER(C15), ISNUMBER(P15)), C15-P15, "") -> 1.1505 | R15: =IF(AND(ISNUMBER(B15), ISNUMBER(L15)), B15-L15, "") -> 1.5998
A16: 42022 | E16: =IF(AND(ISNUMBER(B16), ISNUMBER(D16)), B16-D16, "") | F16: 207.87 | I16: =IF(AND(ISNUMBER(B16), ISNUMBER(G16)), B16-G16, "") | K16: =F16/F15-1 -> -0.0022559278 | Q16: =IF(AND(ISNUMBER(C16), ISNUMBER(P16)), C16-P16, "") | R16: =IF(AND(ISNUMBER(B16), ISNUMBER(L16)), B16-L16, "")
A17: 42023 | D17: 3.52 | E17: =IF(AND(ISNUMBER(B17), ISNUMBER(D17)), B17-D17, "") | F17: 216.21 | H17: 3.23 | I17: =IF(AND(ISNUMBER(B17), ISNUMBER(G17)), B17-G17, "") | J17: 92.52 | K17: =F17/F16-1 -> 0.04012123 | L17: 0.196 | M17: -0.03 | Q17: =IF(AND(ISNUMBER(C17), ISNUMBER(P17)), C17-P17, "") | R17: =IF(AND(ISNUMBER(B17), ISNUMBER(L17)), B17-L17, "")
A18: 42024 | B18: 1.788 | C18: 2.3777 | D18: 3.49 | E18: =IF(AND(ISNUMBER(B18), ISNUMBER(D18)), B18-D18, "") -> -1.702 | F18: 211.18 | G18: 0.4914 | H18: 3.23 | I18: =IF(AND(ISNUMBER(B18), ISNUMBER(G18)), B18-G18, "") -> 1.2966 | J18: 93.046 | K18: =F18/F17-1 -> -0.023264419 | L18: 0.213 | M18: -0.035 | N18: 2022.55 | O18: 4171.21 | P18: 1.2797 | Q18: =IF(AND(ISNUMBER(C18), ISNUMBER(P18)), C18-P18, "") -> 1.098 | R18: =IF(AND(ISNUMBER(B18), ISNUMBER(L18)), B18-L18, "") -> 1.575
A19: 42025 | B19: 1.8717 | C19: 2.4614 | D19: 3.49 | E19: =IF(AND(ISNUMBER(B19), ISNUMBER(D19)), B19-D19, "") -> -1.6183 | F19: 225.1 | G19: 0.5074 | H19: 3.23 | I19: =IF(AND(ISNUMBER(B19), ISNUMBER(G19)), B19-G19, "") -> 1.3643 | J19: 92.904 | K19: =F19/F18-1 -> 0.065915333 | L19: 0.242 | M19: -0.035 | N19: 2032.12 | O19: 4192.0898 | P19: 1.3494 | Q19: =IF(AND(ISNUMBER(C19), ISNUMBER(P19)), C19-P19, "") -> 1.112 | R19: =IF(AND(ISNUMBER(B19), ISNUMBER(L19)), B19-L19, "") -> 1.6297
A20: 42026 | B20: 1.8631 | C20: 2.4385 | D20: 3.48 | E20: =IF(AND(ISNUMBER(B20), ISNUMBER(D20)), B20-D20, "") -> -1.6169 | F20: 231.92 | G20: 0.5174 | H20: 3.22 | I20: =IF(AND(ISNUMBER(B20), ISNUMBER(G20)), B20-G20, "") -> 1.3457 | J20: 94.077 | K20: =F20/F19-1 -> 0.030297645 | L20: 0.31 | M20: -0.022 | N20: 2063.15 | O20: 4270.3599 | P20: 1.3639 | Q20: =IF(AND(ISNUMBER(C20), ISNUMBER(P20)), C20-P20, "") -> 1.0746 | R20: =IF(AND(ISNUMBER(B20), ISNUMBER(L20)), B20-L20, "") -> 1.5531
A21: 42027 | B21: 1.7968 | C21: 2.3735 | E21: =IF(AND(ISNUMBER(B21), ISNUMBER(D21)), B21-D21, "") | F21: 237.01 | G21: 0.4864 | I21: =IF(AND(ISNUMBER(B21), ISNUMBER(G21)), B21-G21, "") -> 1.3104 | J21: 94.762 | K21: =F21/F20-1 -> 0.021947223 | L21: 0.228 | M21: -0.021 | N21: 2051.82 | O21: 4278.1401 | P21: 1.308 | Q21: =IF(AND(ISNUMBER(C21), ISNUMBER(P21)), C21-P21, "") -> 1.0655 | R21: =IF(AND(ISNUMBER(B21), ISNUMBER(L21)), B21-L21, "") -> 1.5688
A22: 42029 | E22: =IF(AND(ISNUMBER(B22), ISNUMBER(D22)), B22-D22, "") | F22: 251.78 | I22: =IF(AND(ISNUMBER(B22), ISNUMBER(G22)), B22-G22, "") | K22: =F22/F21-1 -> 0.062318046 | Q22: =IF(AND(ISNUMBER(C22), ISNUMBER(P22)), C22-P22, "") | R22: =IF(AND(ISNUMBER(B22), ISNUMBER(L22)), B22-L22, "")
A23: 42030 | B23: 1.8241 | C23: 2.3972 | E23: =IF(AND(ISNUMBER(B23), ISNUMBER(D23)), B23-D23, "") | F23: 271.61 | G23: 0.5107 | H23: 3.21 | I23: =IF(AND(ISNUMBER(B23), ISNUMBER(G23)), B23-G23, "") -> 1.3134 | J23: 94.802 | K23: =F23/F22-1 -> 0.078759234 | L23: 0.224 | M23: -0.018 | N23: 2057.09 | O23: 4275.7202 | P23: 1.3372 | Q23: =IF(AND(ISNUMBER(C23), ISNUMBER(P23)), C23-P23, "") -> 1.06 | R23: =IF(AND(ISNUMBER(B23), ISNUMBER(L23)), B23-L23, "") -> 1.6001
A24: 42031 | B24: 1.8231 | C24: 2.3999 | D24: 3.45 | E24: =IF(AND(ISNUMBER(B24), ISNUMBER(D24)), B24-D24, "") -> -1.6269 | F24: 261.76 | G24: 0.5105 | H24: 3.21 | I24: =IF(AND(ISNUMBER(B24), ISNUMBER(G24)), B24-G24, "") -> 1.3126 | J24: 94.022 | K24: =F24/F23-1 -> -0.036265233 | L24: 0.254 | M24: -0.018 | N24: 2029.55 | O24: 4165.5 | P24: 1.3354 | Q24: =IF(AND(ISNUMBER(C24), ISNUMBER(P24)), C24-P24, "") -> 1.0645 | R24: =IF(AND(ISNUMBER(B24), ISNUMBER(L24)), B24-L24, "") -> 1.5691
A25: 42032 | B25: 1.7207 | C25: 2.2908 | E25: =IF(AND(ISNUMBER(B25), ISNUMBER(D25)), B25-D25, "") | F25: 235.94 | G25: 0.4654 | I25: =IF(AND(ISNUMBER(B25), ISNUMBER(G25)), B25-G25, "") -> 1.2553 | J25: 94.467 | K25: =F25/F24-1 -> -0.098639976 | L25: 0.285 | M25: 0 | N25: 2002.16 | O25: 4140.3799 | P25: 1.2391 | Q25: =IF(AND(ISNUMBER(C25), ISNUMBER(P25)), C25-P25, "") -> 1.0517 | R25: =IF(AND(ISNUMBER(B25), ISNUMBER(L25)), B25-L25, "") -> 1.4357
A26: 42033 | B26: 1.7512 | C26: 2.3148 | D26: 3.5 | E26: =IF(AND(ISNUMBER(B26), ISNUMBER(D26)), B26-D26, "") -> -1.7488 | F26: 234.12 | G26: 0.5158 | H26: 3.17 | I26: =IF(AND(ISNUMBER(B26), ISNUMBER(G26)), B26-G26, "") -> 1.2354 | J26: 94.782 | K26: =F26/F25-1 -> -0.0077138255 | L26: 0.287 | M26: 0.001 | N26: 2021.25 | O26: 4181.3501 | P26: 1.2698 | Q26: =IF(AND(ISNUMBER(C26), ISNUMBER(P26)), C26-P26, "") -> 1.045 | R26: =IF(AND(ISNUMBER(B26), ISNUMBER(L26)), B26-L26, "") -> 1.4642
A27: 42034 | B27: 1.6407 | C27: 2.2222 | D27: 3.51 | E27: =IF(AND(ISNUMBER(B27), ISNUMBER(D27)), B27-D27, "") -> -1.8693 | F27: 229.67 | G27: 0.4488 | H27: 3.19 | I27: =IF(AND(ISNUMBER(B27), ISNUMBER(G27)), B27-G27, "") -> 1.1919 | J27: 94.804 | K27: =F27/F26-1 -> -0.019007347 | L27: 0.271 | N27: 1994.99 | O27: 4148.4302 | P27: 1.1548 | Q27: =IF(AND(ISNUMBER(C27), ISNUMBER(P27)), C27-P27, "") -> 1.0674 | R27: =IF(AND(ISNUMBER(B27), ISNUMBER(L27)), B27-L27, "") -> 1.3697
A28: 42036 | E28: =IF(AND(ISNUMBER(B28), ISNUMBER(D28)), B28-D28, "") | F28: 231.1 | I28: =IF(AND(ISNUMBER(B28), ISNUMBER(G28)), B28-G28, "") | K28: =F28/F27-1 -> 0.0062263247 | Q28: =IF(AND(ISNUMBER(C28), ISNUMBER(P28)), C28-P28, "") | R28: =IF(AND(ISNUMBER(B28), ISNUMBER(L28)), B28-L28, "")
A29: 42037 | B29: 1.6642 | C29: 2.2503 | D29: 3.52 | E29: =IF(AND(ISNUMBER(B29), ISNUMBER(D29)), B29-D29, "") -> -1.8558 | F29: 227.3 | G29: 0.4586 | I29: =IF(AND(ISNUMBER(B29), ISNUMBER(G29)), B29-G29, "") -> 1.2056 | J29: 94.504 | K29: =F29/F28-1 -> -0.016443098 | L29: 0.284 | M29: 0.012 | N29: 2020.85 | O29: 4188.5898 | P29: 1.1789 | Q29: =IF(AND(ISNUMBER(C29), ISNUMBER(P29)), C29-P29, "") -> 1.0714 | R29: =IF(AND(ISNUMBER(B29), ISNUMBER(L29)), B29-L29, "") -> 1.3802
A30: 42038 | B30: 1.7915 | C30: 2.3792 | D30: 3.49 | E30: =IF(AND(ISNUMBER(B30), ISNUMBER(D30)), B30-D30, "") -> -1.6985 | F30: 227.86 | G30: 0.5079 | H30: 3.22 | I30: =IF(AND(ISNUMBER(B30), ISNUMBER(G30)), B30-G30, "") -> 1.2836 | J30: 93.6 | K30: =F30/F29-1 -> 0.0024637044 | L30: 0.361 | M30: 0.022 | N30: 2050.03 | O30: 4229.1499 | P30: 1.2889 | Q30: =IF(AND(ISNUMBER(C30), ISNUMBER(P30)), C30-P30, "") -> 1.0903 | R30: =IF(AND(ISNUMBER(B30), ISNUMBER(L30)), B30-L30, "") -> 1.4305
A31: 42039 | B31: 1.7513 | C31: 2.3481 | E31: =IF(AND(ISNUMBER(B31), ISNUMBER(D31)), B31-D31, "") | F31: 224.98 | G31: 0.4842 | I31: =IF(AND(ISNUMBER(B31), ISNUMBER(G31)), B31-G31, "") -> 1.2671 | J31: 93.986 | K31: =F31/F30-1 -> -0.01263934 | L31: 0.376 | M31: 0.025 | N31: 2041.51 | O31: 4221.2002 | P31: 1.2484 | Q31: =IF(AND(ISNUMBER(C31), ISNUMBER(P31)), C31-P31, "") -> 1.0997 | R31: =IF(AND(ISNUMBER(B31), ISNUMBER(L31)), B31-L31, "") -> 1.3753
A32: 42040 | B32: 1.8204 | C32: 2.4318 | D32: 3.46 | E32: =IF(AND(ISNUMBER(B32), ISNUMBER(D32)), B32-D32, "") -> -1.6396 | F32: 218.76 | G32: 0.5198 | H32: 3.2 | I32: =IF(AND(ISNUMBER(B32), ISNUMBER(G32)), B32-G32, "") -> 1.3006 | J32: 93.569 | K32: =F32/F31-1 -> -0.027646902 | L32: 0.354 | M32: 0.044 | N32: 2062.52 | O32: 4256.1802 | P32: 1.3036 | Q32: =IF(AND(ISNUMBER(C32), ISNUMBER(P32)), C32-P32, "") -> 1.1282 | R32: =IF(AND(ISNUMBER(B32), ISNUMBER(L32)), B32-L32, "") -> 1.4664
A33: 42041 | B33: 1.9567 | C33: 2.5287 | D33: 3.46 | E33: =IF(AND(ISNUMBER(B33), ISNUMBER(D33)), B33-D33, "") -> -1.5033 | F33: 223.37 | G33: 0.6435 | H33: 3.19 | I33: =IF(AND(ISNUMBER(B33), ISNUMBER(G33)), B33-G33, "") -> 1.3132 | J33: 94.698 | K33: =F33/F32-1 -> 0.021073322 | L33: 0.334 | M33: 0.027 | N33: 2055.47 | O33: 4228.6802 | P33: 1.4788 | Q33: =IF(AND(ISNUMBER(C33), ISNUMBER(P33)), C33-P33, "") -> 1.0499 | R33: =IF(AND(ISNUMBER(B33), ISNUMBER(L33)), B33-L33, "") -> 1.6227
A34: 42043 | E34: =IF(AND(ISNUMBER(B34), ISNUMBER(D34)), B34-D34, "") | F34: 222.08 | I34: =IF(AND(ISNUMBER(B34), ISNUMBER(G34)), B34-G34, "") | K34: =F34/F33-1 -> -0.0057751712 | Q34: =IF(AND(ISNUMBER(C34), ISNUMBER(P34)), C34-P34, "") | R34: =IF(AND(ISNUMBER(B34), ISNUMBER(L34)), B34-L34, "")
A35: 42044 | B35: 1.9775 | C35: 2.5528 | E35: =IF(AND(ISNUMBER(B35), ISNUMBER(D35)), B35-D35, "") | F35: 221 | G35: 0.6517 | I35: =IF(AND(ISNUMBER(B35), ISNUMBER(G35)), B35-G35, "") -> 1.3258 | J35: 94.449 | K35: =F35/F34-1 -> -0.0048631124 | L35: 0.349 | M35: 0.043 | N35: 2046.74 | O35: 4216.0898 | P35: 1.5069 | Q35: =IF(AND(ISNUMBER(C35), ISNUMBER(P35)), C35-P35, "") -> 1.0459 | R35: =IF(AND(ISNUMBER(B35), ISNUMBER(L35)), B35-L35, "") -> 1.6285
A36: 42045 | B36: 1.9967 | C36: 2.5763 | D36: 3.43 | E36: =IF(AND(ISNUMBER(B36), ISNUMBER(D36)), B36-D36, "") -> -1.4333 | F36: 219.7 | G36: 0.6499 | H36: 3.2 | I36: =IF(AND(ISNUMBER(B36), ISNUMBER(G36)), B36-G36, "") -> 1.3468 | J36: 94.758 | K36: =F36/F35-1 -> -0.0058823529 | L36: 0.387 | M36: 0.045 | N36: 2068.59 | O36: 4281.1602 | P36: 1.512 | Q36: =IF(AND(ISNUMBER(C36), ISNUMBER(P36)), C36-P36, "") -> 1.0643 | R36: =IF(AND(ISNUMBER(B36), ISNUMBER(L36)), B36-L36, "") -> 1.6097
A37: 42046 | B37: 2.0176 | C37: 2.5863 | E37: =IF(AND(ISNUMBER(B37), ISNUMBER(D37)), B37-D37, "") | F37: 219.39 | G37: 0.6642 | I37: =IF(AND(ISNUMBER(B37), ISNUMBER(G37)), B37-G37, "") -> 1.3534 | J37: 94.985 | K37: =F37/F36-1 -> -0.001411015 | N37: 2068.53 | O37: 4297.2798 | P37: 1.5419 | Q37: =IF(AND(ISNUMBER(C37), ISNUMBER(P37)), C37-P37, "") -> 1.0444 | R37: =IF(AND(ISNUMBER(B37), ISNUMBER(L37)), B37-L37, "")
A38: 42047 | B38: 1.9844 | C38: 2.5755 | E38: =IF(AND(ISNUMBER(B38), ISNUMBER(D38)), B38-D38, "") | F38: 222.2 | G38: 0.6242 | I38: =IF(AND(ISNUMBER(B38), ISNUMBER(G38)), B38-G38, "") -> 1.3602 | J38: 94.094 | K38: =F38/F37-1 -> 0.012808241 | L38: 0.391 | M38: 0.044 | N38: 2088.48 | O38: 4347.9702 | P38: 1.4908 | Q38: =IF(AND(ISNUMBER(C38), ISNUMBER(P38)), C38-P38, "") -> 1.0847 | R38: =IF(AND(ISNUMBER(B38), ISNUMBER(L38)), B38-L38, "") -> 1.5934
A39: 42048 | B39: 2.0504 | C39: 2.6478 | D39: 3.38 | E39: =IF(AND(ISNUMBER(B39), ISNUMBER(D39)), B39-D39, "") -> -1.3296 | F39: 234.25 | G39: 0.6411 | H39: 3.16 | I39: =IF(AND(ISNUMBER(B39), ISNUMBER(G39)), B39-G39, "") -> 1.4093 | J39: 94.201 | K39: =F39/F38-1 -> 0.054230423 | L39: 0.419 | M39: 0.041 | N39: 2096.99 | O39: 4384.0298 | P39: 1.5377 | Q39: =IF(AND(ISNUMBER(C39), ISNUMBER(P39)), C39-P39, "") -> 1.1101 | R39: =IF(AND(ISNUMBER(B39), ISNUMBER(L39)), B39-L39, "") -> 1.6314
A40: 42050 | E40: =IF(AND(ISNUMBER(B40), ISNUMBER(D40)), B40-D40, "") | F40: 231.03 | I40: =IF(AND(ISNUMBER(B40), ISNUMBER(G40)), B40-G40, "") | K40: =F40/F39-1 -> -0.013745998 | Q40: =IF(AND(ISNUMBER(C40), ISNUMBER(P40)), C40-P40, "") | R40: =IF(AND(ISNUMBER(B40), ISNUMBER(L40)), B40-L40, "")
...

Sheet corr
A1: Date | B1: SPX | C1: NDX | D1: BTC Spot | E1: XAU | F1: MXWO | G1: DXY | H1: RTY | I1: ETH Spot
A2: 42005 | D2: 314.49 | E2: 1181.98 | F2: 1709.68 | G2: 90.276
A3: 42006 | B3: 2058.2 | C3: 4230.24 | D3: 314.73 | E3: 1188.39 | F3: 1704.71 | G3: 91.08 | H3: 1198.8
A4: 42008 | D4: 266.26
A5: 42009 | B5: 2020.58 | C5: 4160.96 | D5: 270.93 | E5: 1204.86 | F5: 1671.25 | G5: 91.378 | H5: 1181.346
A6: 42010 | B6: 2002.61 | C6: 4110.83 | D6: 286.41 | E6: 1218.58 | F6: 1654.38 | G6: 91.499 | H6: 1161.311
A7: 42011 | B7: 2025.9 | C7: 4160 | D7: 296.13 | E7: 1211.41 | F7: 1662.22 | G7: 91.89 | H7: 1175.968
A8: 42012 | B8: 2062.14 | C8: 4240.55 | D8: 293.83 | E8: 1208.79 | F8: 1694.17 | G8: 92.368 | H8: 1196.121
A9: 42013 | B9: 2044.81 | C9: 4213.28 | D9: 289.81 | E9: 1223.25 | F9: 1683.8 | G9: 91.935 | H9: 1185.676
A10: 42015 | D10: 268.12
A11: 42016 | B11: 2028.26 | C11: 4169.97 | D11: 270.65 | E11: 1233.31 | F11: 1676.71 | G11: 91.983 | H11: 1180.093
A12: 42017 | B12: 2023.03 | C12: 4166.2 | D12: 236.05 | E12: 1230.64 | F12: 1678.19 | G12: 92.31 | H12: 1180.636
A13: 42018 | B13: 2011.27 | C13: 4145.84 | D13: 183.07 | E13: 1228.72 | F13: 1665.38 | G13: 92.161 | H13: 1177.06
A14: 42019 | B14: 1992.67 | C14: 4089.65 | D14: 206.68 | E14: 1262.75 | F14: 1662.44 | G14: 92.352 | H14: 1154.709
A15: 42020 | B15: 2019.42 | C15: 4142.14 | D15: 208.34 | E15: 1280.45 | F15: 1675.15 | G15: 92.52 | H15: 1176.655
A16: 42022 | D16: 207.87
A17: 42023 | D17: 216.21 | E17: 1275.65 | F17: 1681.9 | G17: 92.52
A18: 42024 | B18: 2022.55 | C18: 4171.21 | D18: 211.18 | E18: 1295.32 | F18: 1685.27 | G18: 93.046 | H18: 1170.254
A19: 42025 | B19: 2032.12 | C19: 4192.09 | D19: 225.1 | E19: 1293.09 | F19: 1694.34 | G19: 92.904 | H19: 1166.251
A20: 42026 | B20: 2063.15 | C20: 4270.36 | D20: 231.92 | E20: 1302.25 | F20: 1710.47 | G20: 94.077 | H20: 1190.371
A21: 42027 | B21: 2051.82 | C21: 4278.14 | D21: 237.01 | E21: 1294.08 | F21: 1707.74 | G21: 94.762 | H21: 1188.928
A22: 42029 | D22: 251.78
A23: 42030 | B23: 2057.09 | C23: 4275.72 | D23: 271.61 | E23: 1281.4 | F23: 1712.55 | G23: 94.802 | H23: 1200.74
A24: 42031 | B24: 2029.55 | C24: 4165.5 | D24: 261.76 | E24: 1292.34 | F24: 1705.6 | G24: 94.022 | H24: 1194.658
A25: 42032 | B25: 2002.16 | C25: 4140.38 | D25: 235.94 | E25: 1284.49 | F25: 1689.2 | G25: 94.467 | H25: 1175.115
A26: 42033 | B26: 2021.25 | C26: 4181.35 | D26: 234.12 | E26: 1257.27 | F26: 1693.81 | G26: 94.782 | H26: 1190.182
A27: 42034 | B27: 1994.99 | C27: 4148.43 | D27: 229.67 | E27: 1283.79 | F27: 1677.54 | G27: 94.804 | H27: 1165.392
A28: 42036 | D28: 231.1
A29: 42037 | B29: 2020.85 | C29: 4188.59 | D29: 227.3 | E29: 1274.41 | F29: 1694.35 | G29: 94.504 | H29: 1175.515
A30: 42038 | B30: 2050.03 | C30: 4229.15 | D30: 227.86 | E30: 1260.52 | F30: 1715.22 | G30: 93.6 | H30: 1196.988
A31: 42039 | B31: 2041.51 | C31: 4221.2 | D31: 224.98 | E31: 1269.35 | F31: 1715.13 | G31: 93.986 | H31: 1191.442
A32: 42040 | B32: 2062.52 | C32: 4256.18 | D32: 218.76 | E32: 1264.82 | F32: 1727.49 | G32: 93.569 | H32: 1208.707
A33: 42041 | B33: 2055.47 | C33: 4228.68 | D33: 223.37 | E33: 1234.04 | F33: 1720.55 | G33: 94.698 | H33: 1205.464
A34: 42043 | D34: 222.08
A35: 42044 | B35: 2046.74 | C35: 4216.09 | D35: 221 | E35: 1239.03 | F35: 1714.23 | G35: 94.449 | H35: 1195.826
A36: 42045 | B36: 2068.59 | C36: 4281.16 | D36: 219.7 | E36: 1233.55 | F36: 1725.83 | G36: 94.758 | H36: 1203.179
A37: 42046 | B37: 2068.53 | C37: 4297.28 | D37: 219.39 | E37: 1218.83 | F37: 1721.58 | G37: 94.985 | H37: 1201.555
A38: 42047 | B38: 2088.48 | C38: 4347.97 | D38: 222.2 | E38: 1221.98 | F38: 1741.22 | G38: 94.094 | H38: 1216.266
A39: 42048 | B39: 2096.99 | C39: 4384.03 | D39: 234.25 | E39: 1229.76 | F39: 1752.18 | G39: 94.201 | H39: 1223.131
A40: 42050 | D40: 231.03
...

Sheet move
A1: Date | B1: XBTUSD BGN Curncy (L1) | C1: MOVE Index (R1) | D1: VIX Index (R1)
A2: 42151 | B2: 235.57 | C2: 83.9933 | D2: 13.27
A3: 42152 | B3: 236.08 | C3: 82.7222 | D3: 13.31
A4: 42153 | B4: 235.95 | C4: 82.6996 | D4: 13.84
A5: 42155 | B5: 231.78
A6: 42156 | B6: 221.98 | C6: 83.5495 | D6: 13.97
A7: 42157 | B7: 225.09 | C7: 87.4796 | D7: 14.24
A8: 42158 | B8: 226.96 | C8: 91.8063 | D8: 13.66
A9: 42159 | B9: 223.68 | C9: 92.2056 | D9: 14.71
A10: 42160 | B10: 224.88 | C10: 88.9414 | D10: 14.21
A11: 42162 | B11: 222.48
A12: 42163 | B12: 228.48 | C12: 87.6084 | D12: 15.29
A13: 42164 | B13: 229.81 | C13: 87.1697 | D13: 14.47
A14: 42165 | B14: 228.46 | C14: 89.7596 | D14: 13.22
A15: 42166 | B15: 228.8 | C15: 87.7673 | D15: 12.85
A16: 42167 | B16: 229.9 | C16: 87.6824 | D16: 13.78
A17: 42169 | B17: 232.17
A18: 42170 | B18: 235.93 | C18: 86.0026 | D18: 15.39
A19: 42171 | B19: 246.32 | C19: 85.6971 | D19: 14.81
A20: 42172 | B20: 250.31 | C20: 82.4194 | D20: 14.5
A21: 42173 | B21: 249.08 | C21: 82.5575 | D21: 13.19
A22: 42174 | B22: 246.04 | C22: 84.7442 | D22: 13.96
A23: 42176 | B23: 241.92
A24: 42177 | B24: 247.24 | C24: 84.4485 | D24: 12.74
A25: 42178 | B25: 244.36 | C25: 84.2001 | D25: 12.11
A26: 42179 | B26: 240.98 | C26: 82.6809 | D26: 13.26
A27: 42180 | B27: 240.66 | C27: 83.3241 | D27: 14.01
A28: 42181 | B28: 241.27 | C28: 84.3188 | D28: 14.02
A29: 42183 | B29: 248.63
A30: 42184 | B30: 255.53 | C30: 89.7561 | D30: 18.85
A31: 42185 | B31: 260.97 | C31: 92.2575 | D31: 18.23
A32: 42186 | B32: 258.85 | C32: 90.2884 | D32: 16.09
A33: 42187 | B33: 255.81 | C33: 87.9611 | D33: 16.79
A34: 42188 | B34: 255.22 | C34: 87.9611
A35: 42190 | B35: 269.69
A36: 42191 | B36: 273.94 | C36: 86.1804 | D36: 17.01
A37: 42192 | B37: 265.92 | C37: 90.4681 | D37: 16.09
A38: 42193 | B38: 268.05 | C38: 89.4277 | D38: 19.66
A39: 42194 | B39: 270.31 | C39: 89.3438 | D39: 19.97
A40: 42195 | B40: 287.13 | C40: 90.2308 | D40: 16.83
...

Sheet japan-yen
A1: Date | B1: BTC Spot | C1: USDJPY | D1: 10Y US Minus 10Y Japan Yield | E1: 2Y US Minus 2Y Japan Yield
A2: 42005 | B2: 314.49 | C2: 119.74
A3: 42006 | B3: 314.73 | C3: 120.5
A4: 42008 | B4: 266.26
A5: 42009 | B5: 270.93 | C5: 119.64 | D5: 1.712 | E5: 0.6718
A6: 42010 | B6: 286.41 | C6: 118.39 | D6: 1.6522 | E6: 0.646
A7: 42011 | B7: 296.13 | C7: 119.26 | D7: 1.6712 | E7: 0.6301
A8: 42012 | B8: 293.83 | C8: 119.66 | D8: 1.7299 | E8: 0.6271
A9: 42013 | B9: 289.81 | C9: 118.5 | D9: 1.6759 | E9: 0.592
A10: 42015 | B10: 268.12 | D10: 1.6759 | E10: 0.592
A11: 42016 | B11: 270.65 | C11: 118.35 | D11: 1.638 | E11: 0.5759
A12: 42017 | B12: 236.05 | C12: 117.93 | D12: 1.642 | E12: 0.5588
A13: 42018 | B13: 183.07 | C13: 117.33 | D13: 1.6063 | E13: 0.5206
A14: 42019 | B14: 206.68 | C14: 116.17 | D14: 1.4674 | E14: 0.4312
A15: 42020 | B15: 208.34 | C15: 117.51 | D15: 1.5998 | E15: 0.5035
A16: 42022 | B16: 207.87 | D16: 1.5998 | E16: 0.5035
A17: 42023 | B17: 216.21 | C17: 117.56 | D17: 1.6413 | E17: 0.5035
A18: 42024 | B18: 211.18 | C18: 118.82 | D18: 1.575 | E18: 0.5164
A19: 42025 | B19: 225.1 | C19: 117.97 | D19: 1.6297 | E19: 0.5324
A20: 42026 | B20: 231.92 | C20: 118.49 | D20: 1.5531 | E20: 0.5294
A21: 42027 | B21: 237.01 | C21: 117.77 | D21: 1.5688 | E21: 0.4974
A22: 42029 | B22: 251.78 | D22: 1.5688 | E22: 0.4974
A23: 42030 | B23: 271.61 | C23: 118.46 | D23: 1.6001 | E23: 0.5237
A24: 42031 | B24: 261.76 | C24: 117.87 | D24: 1.5691 | E24: 0.5235
A25: 42032 | B25: 235.94 | C25: 117.54 | D25: 1.4352 | E25: 0.4604
A26: 42033 | B26: 234.12 | C26: 118.29 | D26: 1.4642 | E26: 0.5098
A27: 42034 | B27: 229.67 | C27: 117.49 | D27: 1.3692 | E27: 0.4428
A28: 42036 | B28: 231.1 | D28: 1.3692 | E28: 0.4428
A29: 42037 | B29: 227.3 | C29: 117.57 | D29: 1.3802 | E29: 0.4306
A30: 42038 | B30: 227.86 | C30: 117.57 | D30: 1.4305 | E30: 0.4809
A31: 42039 | B31: 224.98 | C31: 117.28 | D31: 1.3753 | E31: 0.4522
A32: 42040 | B32: 218.76 | C32: 117.53 | D32: 1.4664 | E32: 0.4698
A33: 42041 | B33: 223.37 | C33: 119.12 | D33: 1.6227 | E33: 0.6095
A34: 42043 | B34: 222.08 | D34: 1.6227 | E34: 0.6095
A35: 42044 | B35: 221 | C35: 118.64 | D35: 1.6285 | E35: 0.6017
A36: 42045 | B36: 219.7 | C36: 119.43 | D36: 1.6092 | E36: 0.5979
A37: 42046 | B37: 219.39 | C37: 120.46 | D37: 1.6301 | E37: 0.6122
A38: 42047 | B38: 222.2 | C38: 119.11 | D38: 1.5939 | E38: 0.5742
A39: 42048 | B39: 234.25 | C39: 118.75 | D39: 1.6319 | E39: 0.5941
A40: 42050 | B40: 231.03 | D40: 1.6319 | E40: 0.5941
...

Sheet GOLD_ETFs
A1: Date | B1: 001.046 Index (L1) | C1: HOLDTOT Index (R2) | D1: 924.046 Index (R1) | E1: XAUUSD BGN Curncy (R2) | F1: ETFGTOTL Index (L2) | G1: XAG BGN Curncy (R1)
A2: 36528 | E2: 289 | G2: 5.405
A3: 36529 | E3: 282.25 | G3: 5.325
A4: 36530 | E4: 280 | G4: 5.145
A5: 36531 | E5: 281.1 | G5: 5.12
A6: 36532 | E6: 281.75 | G6: 5.175
A7: 36535 | E7: 281.48 | G7: 5.145
A8: 36536 | E8: 283.25 | G8: 5.16
A9: 36537 | E9: 282.35 | G9: 5.105
A10: 36538 | E10: 284.25 | G10: 5.11
A11: 36539 | E11: 284.2 | G11: 5.125
A12: 36542 | E12: 285.5 | G12: 5.11
A13: 36543 | E13: 288.65 | G13: 5.12
... A21: 36553 | E21: 283.25 | G21: 5.26
A22: 36556 | B22: 1077.58 | D22: 12.7 | E22: 283.5 | G22: 5.245
A23: 36557 | E23: 282.63 | G23: 5.195
A24: 36558 | E24: 284.75 | G24: 5.18
A25: 36559 | E25: 287.45 | G25: 5.23
A26: 36560 | E26: 310.3 | G26: 5.285
A27: 36563 | E27: 302.75 | G27: 5.225
A28: 36564 | E28: 301.75 | G28: 5.275
A29: 36565 | E29: 306.75 | G29: 5.36
A30: 36566 | E30: 315 | G30: 5.36
A31: 36567 | E31: 310.95 | G31: 5.29
A32: 36570 | E32: 308.15 | G32: 5.235
A33: 36571 | E33: 301.75 | G33: 5.225
A34: 36572 | E34: 302.5 | G34: 5.26
... A42: 36584 | E42: 291.75 | G42: 5.06
A43: 36585 | B43: 1075.76 | D43: 12.7 | E43: 292.2 | G43: 5.07
A44: 36586 | E44: 289.75 | G44: 5.08
A45: 36587 | E45: 288.5 | G45: 5.03
A46: 36588 | E46: 288.8 | G46: 5.11
A47: 36591 | E47: 287.63 | G47: 5.06
A48: 36592 | E48: 293.25 | G48: 5.075
A49: 36593 | E49: 288.13 | G49: 5.09
A50: 36594 | E50: 291.2 | G50: 5.1
A51: 36595 | E51: 289 | G51: 5.06
A52: 36598 | E52: 290.7 | G52: 5.07
A53: 36599 | E53: 288.88 | G53: 5.095
A54: 36600 | E54: 288.85 | G54: 5.12
...

Sheet BTC_ETH_ETFs
A1: Date | B1: BTC ETF | C1: ETH ETF | D1: MSTR ($M) | E1: Gold ETF | F1: BTC Spot | G1: ETH Spot | H1: BTC/ ETH | I1: Gold Spot | J1: MetaPlanet Purchases (~$M) | K1: Spot ETFs & Strategy | L1: Rolling 20D Flow Sum
A2: 45302 | B2: 655.3 | C2: #N/A | D2: 0 | E2: =_xlfn.XLOOKUP(A2,GOLD_ETFs!A:A,GOLD_ETFs!F:F) -> 85230800 | F2: =_xlfn.XLOOKUP(A2,spread!A:A,spread!F:F) -> 46163.13 | G2: =_xlfn.XLOOKUP(A2,corr!A:A,corr!I:I) -> 2604.02 | H2: =F2/G2 -> 17.72764 | I2: =_xlfn.XLOOKUP(A2,corr!A:A,corr!E:E,,1) -> 2028.91 | J2: =(_xlfn.XLOOKUP(BTC_ETH_ETFs!A2,MetaPlanet_BTC!A:A,MetaPlanet_BTC!C:C)*F2)/ 1000000 -> #N/A | K2: =B2+D2 -> 655.3
A3: 45303 | B3: 203 | C3: #N/A | D3: 0 | E3: =_xlfn.XLOOKUP(A3,GOLD_ETFs!A:A,GOLD_ETFs!F:F) -> 85121880 | F3: =_xlfn.XLOOKUP(A3,spread!A:A,spread!F:F) -> 43426.6 | G3: =_xlfn.XLOOKUP(A3,corr!A:A,corr!I:I) -> 2523.675 | H3: =F3/G3 -> 17.207683 | I3: =_xlfn.XLOOKUP(A3,corr!A:A,corr!E:E,,1) -> 2049.06 | J3: =(_xlfn.XLOOKUP(BTC_ETH_ETFs!A3,MetaPlanet_BTC!A:A,MetaPlanet_BTC!C:C)*F3)/ 1000000 -> #N/A | K3: =B3+D3 -> 203
A4: 45306 | B4: 0 | C4: #N/A | D4: 0 | E4: =_xlfn.XLOOKUP(A4,GOLD_ETFs!A:A,GOLD_ETFs!F:F) -> 85123128 | F4: =_xlfn.XLOOKUP(A4,spread!A:A,spread!F:F) -> 42687.31 | G4: =_xlfn.XLOOKUP(A4,corr!A:A,corr!I:I) -> 2520.518 | H4: =F4/G4 -> 16.935927 | I4: =_xlfn.XLOOKUP(A4,corr!A:A,corr!E:E,,1) -> 2056.55 | J4: =(_xlfn.XLOOKUP(BTC_ETH_ETFs!A4,MetaPlanet_BTC!A:A,MetaPlanet_BTC!C:C)*F4)/ 1000000 -> #N/A | K4: =B4+D4 -> 0
A5: 45307 | B5: -52.7 | C5: #N/A | D5: 0 | E5: =_xlfn.XLOOKUP(A5,GOLD_ETFs!A:A,GOLD_ETFs!F:F) -> 85101288 | F5: =_xlfn.XLOOKUP(A5,spread!A:A,spread!F:F) -> 43434.42 | G5: =_xlfn.XLOOKUP(A5,corr!A:A,corr!I:I) -> 2607.052 | H5: =F5/G5 -> 16.660358 | I5: =_xlfn.XLOOKUP(A5,corr!A:A,corr!E:E,,1) -> 2028.44 | J5: =(_xlfn.XLOOKUP(BTC_ETH_ETFs!A5,MetaPlanet_BTC!A:A,MetaPlanet_BTC!C:C)*F5)/ 1000000 -> #N/A | K5: =B5+D5 -> -52.7
A6: 45308 | B6: 453.8 | C6: #N/A | D6: 0 | E6: =_xlfn.XLOOKUP(A6,GOLD_ETFs!A:A,GOLD_ETFs!F:F) -> 85111984 | F6: =_xlfn.XLOOKUP(A6,spread!A:A,spread!F:F) -> 42637.06 | G6: =_xlfn.XLOOKUP(A6,corr!A:A,corr!I:I) -> 2524.21 | H6: =F6/G6 -> 16.891249 | I6: =_xlfn.XLOOKUP(A6,corr!A:A,corr!E:E,,1) -> 2006.25 | J6: =(_xlfn.XLOOKUP(BTC_ETH_ETFs!A6,MetaPlanet_BTC!A:A,MetaPlanet_BTC!C:C)*F6)/ 1000000 -> #N/A | K6: =B6+D6 -> 453.8
A7: 45309 | B7: -126.6 | C7: #N/A | D7: 0 | E7: =_xlfn.XLOOKUP(A7,GOLD_ETFs!A:A,GOLD_ETFs!F:F) -> 85064960 | F7: =_xlfn.XLOOKUP(A7,spread!A:A,spread!F:F) -> 41069.92 | G7: =_xlfn.XLOOKUP(A7,corr!A:A,corr!I:I) -> 2453.965 | H7: =F7/G7 -> 16.736147 | I7: =_xlfn.XLOOKUP(A7,corr!A:A,corr!E:E,,1) -> 2023.34 | J7: =(_xlfn.XLOOKUP(BTC_ETH_ETFs!A7,MetaPlanet_BTC!A:A,MetaPlanet_BTC!C:C)*F7)/ 1000000 -> #N/A | K7: =B7+D7 -> -126.6
A8: 45310 | B8: 43.6 | C8: #N/A | D8: 0 | E8: =_xlfn.XLOOKUP(A8,GOLD_ETFs!A:A,GOLD_ETFs!F:F) -> 85048936 | F8: =_xlfn.XLOOKUP(A8,spread!A:A,spread!F:F) -> 41602.18 | G8: =_xlfn.XLOOKUP(A8,corr!A:A,corr!I:I) -> 2486.953 | H8: =F8/G8 -> 16.728173 | I8: =_xlfn.XLOOKUP(A8,corr!A:A,corr!E:E,,1) -> 2029.49 | J8: =(_xlfn.XLOOKUP(BTC_ETH_ETFs!A8,MetaPlanet_BTC!A:A,MetaPlanet_BTC!C:C)*F8)/ 1000000 -> #N/A | K8: =B8+D8 -> 43.6
A9: 45313 | B9: -87.4 | C9: #N/A | D9: 0 | E9: =_xlfn.XLOOKUP(A9,GOLD_ETFs!A:A,GOLD_ETFs!F:F) -> 84870160 | F9: =_xlfn.XLOOKUP(A9,spread!A:A,spread!F:F) -> 39815.45 | G9: =_xlfn.XLOOKUP(A9,corr!A:A,corr!I:I) -> 2325 | H9: =F9/G9 -> 17.124925 | I9: =_xlfn.XLOOKUP(A9,corr!A:A,corr!E:E,,1) -> 2021.7 | J9: =(_xlfn.XLOOKUP(BTC_ETH_ETFs!A9,MetaPlanet_BTC!A:A,MetaPlanet_BTC!C:C)*F9)/ 1000000 -> #N/A | K9: =B9+D9 -> -87.4
A10: 45314 | B10: -106.1 | C10: #N/A | D10: 0 | E10: =_xlfn.XLOOKUP(A10,GOLD_ETFs!A:A,GOLD_ETFs!F:F) -> 84856600 | F10: =_xlfn.XLOOKUP(A10,spread!A:A,spread!F:F) -> 39201.77 | G10: =_xlfn.XLOOKUP(A10,corr!A:A,corr!I:I) -> 2201.962 | H10: =F10/G10 -> 17.803109 | I10: =_xlfn.XLOOKUP(A10,corr!A:A,corr!E:E,,1) -> 2029.28 | J10: =(_xlfn.XLOOKUP(BTC_ETH_ETFs!A10,MetaPlanet_BTC!A:A,MetaPlanet_BTC!C:C)*F10)/ 1000000 -> #N/A | K10: =B10+D10 -> -106.1
A11: 45315 | B11: -158.3 | C11: #N/A | D11: 0 | E11: =_xlfn.XLOOKUP(A11,GOLD_ETFs!A:A,GOLD_ETFs!F:F) -> 84845984 | F11: =_xlfn.XLOOKUP(A11,spread!A:A,spread!F:F) -> 39765.38 | G11: =_xlfn.XLOOKUP(A11,corr!A:A,corr!I:I) -> 2215.9 | H11: =F11/G11 -> 17.945476 | I11: =_xlfn.XLOOKUP(A11,corr!A:A,corr!E:E,,1) -> 2013.89 | J11: =(_xlfn.XLOOKUP(BTC_ETH_ETFs!A11,MetaPlanet_BTC!A:A,MetaPlanet_BTC!C:C)*F11)/ 1000000 -> #N/A | K11: =B11+D11 -> -158.3
A12: 45316 | B12: -79.8 | C12: #N/A | D12: 0 | E12: =_xlfn.XLOOKUP(A12,GOLD_ETFs!A:A,GOLD_ETFs!F:F) -> 84761336 | F12: =_xlfn.XLOOKUP(A12,spread!A:A,spread!F:F) -> 39904.41 | G12: =_xlfn.XLOOKUP(A12,corr!A:A,corr!I:I) -> 2218.047 | H12: =F12/G12 -> 17.990786 | I12: =_xlfn.XLOOKUP(A12,corr!A:A,corr!E:E,,1) -> 2020.84 | J12: =(_xlfn.XLOOKUP(BTC_ETH_ETFs!A12,MetaPlanet_BTC!A:A,MetaPlanet_BTC!C:C)*F12)/ 1000000 -> #N/A | K12: =B12+D12 -> -79.8
A13: 45317 | B13: 14.8 | C13: #N/A | D13: 0 | E13: =_xlfn.XLOOKUP(A13,GOLD_ETFs!A:A,GOLD_ETFs!F:F) -> 84711848 | F13: =_xlfn.XLOOKUP(A13,spread!A:A,spread!F:F) -> 41994.36 | G13: =_xlfn.XLOOKUP(A13,corr!A:A,corr!I:I) -> 2259.127 | H13: =F13/G13 -> 18.588756 | I13: =_xlfn.XLOOKUP(A13,corr!A:A,corr!E:E,,1) -> 2018.52 | J13: =(_xlfn.XLOOKUP(BTC_ETH_ETFs!A13,MetaPlanet_BTC!A:A,MetaPlanet_BTC!C:C)*F13)/ 1000000 -> #N/A | K13: =B13+D13 -> 14.8
... A21: 45329 | B21: 146 | C21: #N/A | D21: 0 | E21: =_xlfn.XLOOKUP(A21,GOLD_ETFs!A:A,GOLD_ETFs!F:F) -> 84006544 | F21: =_xlfn.XLOOKUP(A21,spread!A:A,spread!F:F) -> 44188.33 | G21: =_xlfn.XLOOKUP(A21,corr!A:A,corr!I:I) -> 2430.01 | H21: =F21/G21 -> 18.184423 | I21: =_xlfn.XLOOKUP(A21,corr!A:A,corr!E:E,,1) -> 2035.36 | J21: =(_xlfn.XLOOKUP(BTC_ETH_ETFs!A21,MetaPlanet_BTC!A:A,MetaPlanet_BTC!C:C)*F21)/ 1000000 -> #N/A | K21: =B21+D21 -> 146
A22: 45330 | B22: 405 | C22: #N/A | D22: 0 | E22: =_xlfn.XLOOKUP(A22,GOLD_ETFs!A:A,GOLD_ETFs!F:F) -> 84050224 | F22: =_xlfn.XLOOKUP(A22,spread!A:A,spread!F:F) -> 45331.74 | G22: =_xlfn.XLOOKUP(A22,corr!A:A,corr!I:I) -> 2425.695 | H22: =F22/G22 -> 18.688145 | I22: =_xlfn.XLOOKUP(A22,corr!A:A,corr!E:E,,1) -> 2034.52 | J22: =(_xlfn.XLOOKUP(BTC_ETH_ETFs!A22,MetaPlanet_BTC!A:A,MetaPlanet_BTC!C:C)*F22)/ 1000000 -> #N/A | K22: =B22+D22 -> 405 | L22: =SUM(K2:K21) -> 1862.8
A23: 45331 | B23: 541.5 | C23: #N/A | D23: 0 | E23: =_xlfn.XLOOKUP(A23,GOLD_ETFs!A:A,GOLD_ETFs!F:F) -> 84031344 | F23: =_xlfn.XLOOKUP(A23,spread!A:A,spread!F:F) -> 47547.04 | G23: =_xlfn.XLOOKUP(A23,corr!A:A,corr!I:I) -> 2504.087 | H23: =F23/G23 -> 18.987775 | I23: =_xlfn.XLOOKUP(A23,corr!A:A,corr!E:E,,1) -> 2024.26 | J23: =(_xlfn.XLOOKUP(BTC_ETH_ETFs!A23,MetaPlanet_BTC!A:A,MetaPlanet_BTC!C:C)*F23)/ 1000000 -> #N/A | K23: =B23+D23 -> 541.5 | L23: =SUM(K3:K22) -> 1612.5
A24: 45334 | B24: 493.4 | C24: #N/A | D24: 0 | E24: =_xlfn.XLOOKUP(A24,GOLD_ETFs!A:A,GOLD_ETFs!F:F) -> 83860432 | F24: =_xlfn.XLOOKUP(A24,spread!A:A,spread!F:F) -> 49843.24 | G24: =_xlfn.XLOOKUP(A24,corr!A:A,corr!I:I) -> 2632.54 | H24: =F24/G24 -> 18.933517 | I24: =_xlfn.XLOOKUP(A24,corr!A:A,corr!E:E,,1) -> 2020.05 | J24: =(_xlfn.XLOOKUP(BTC_ETH_ETFs!A24,MetaPlanet_BTC!A:A,MetaPlanet_BTC!C:C)*F24)/ 1000000 -> #N/A | K24: =B24+D24 -> 493.4 | L24: =SUM(K4:K23) -> 1951
A25: 45335 | B25: 636.3 | C25: #N/A | D25: 0 | E25: =_xlfn.XLOOKUP(A25,GOLD_ETFs!A:A,GOLD_ETFs!F:F) -> 83778584 | F25: =_xlfn.XLOOKUP(A25,spread!A:A,spread!F:F) -> 49563.06 | G25: =_xlfn.XLOOKUP(A25,corr!A:A,corr!I:I) -> 2633.485 | H25: =F25/G25 -> 18.820331 | I25: =_xlfn.XLOOKUP(A25,corr!A:A,corr!E:E,,1) -> 1993.15 | J25: =(_xlfn.XLOOKUP(BTC_ETH_ETFs!A25,MetaPlanet_BTC!A:A,MetaPlanet_BTC!C:C)*F25)/ 1000000 -> #N/A | K25: =B25+D25 -> 636.3 | L25: =SUM(K5:K24) -> 2444.4
A26: 45336 | B26: 339.7 | C26: #N/A | D26: 0 | E26: =_xlfn.XLOOKUP(A26,GOLD_ETFs!A:A,GOLD_ETFs!F:F) -> 83671200 | F26: =_xlfn.XLOOKUP(A26,spread!A:A,spread!F:F) -> 51772.71 | G26: =_xlfn.XLOOKUP(A26,corr!A:A,corr!I:I) -> 2780.5 | H26: =F26/G26 -> 18.619928 | I26: =_xlfn.XLOOKUP(A26,corr!A:A,corr!E:E,,1) -> 1992.33 | J26: =(_xlfn.XLOOKUP(BTC_ETH_ETFs!A26,MetaPlanet_BTC!A:A,MetaPlanet_BTC!C:C)*F26)/ 1000000 -> #N/A | K26: =B26+D26 -> 339.7 | L26: =SUM(K6:K25) -> 3133.4
A27: 45337 | B27: 477.4 | C27: #N/A | D27: 0 | E27: =_xlfn.XLOOKUP(A27,GOLD_ETFs!A:A,GOLD_ETFs!F:F) -> 83585264 | F27: =_xlfn.XLOOKUP(A27,spread!A:A,spread!F:F) -> 51371.31 | G27: =_xlfn.XLOOKUP(A27,corr!A:A,corr!I:I) -> 2796.427 | H27: =F27/G27 -> 18.370338 | I27: =_xlfn.XLOOKUP(A27,corr!A:A,corr!E:E,,1) -> 2004.4 | J27: =(_xlfn.XLOOKUP(BTC_ETH_ETFs!A27,MetaPlanet_BTC!A:A,MetaPlanet_BTC!C:C)*F27)/ 1000000 -> #N/A | K27: =B27+D27 -> 477.4 | L27: =SUM(K7:K26) -> 3019.3
A28: 45338 | B28: 330.3 | C28: #N/A | D28: 0 | E28: =_xlfn.XLOOKUP(A28,GOLD_ETFs!A:A,GOLD_ETFs!F:F) -> 83552456 | F28: =_xlfn.XLOOKUP(A28,spread!A:A,spread!F:F) -> 52016.4 | G28: =_xlfn.XLOOKUP(A28,corr!A:A,corr!I:I) -> 2791.978 | H28: =F28/G28 -> 18.630663 | I28: =_xlfn.XLOOKUP(A28,corr!A:A,corr!E:E,,1) -> 2013.59 | J28: =(_xlfn.XLOOKUP(BTC_ETH_ETFs!A28,MetaPlanet_BTC!A:A,MetaPlanet_BTC!C:C)*F28)/ 1000000 -> #N/A | K28: =B28+D28 -> 330.3 | L28: =SUM(K8:K27) -> 3623.3
A29: 45341 | B29: 0 | C29: #N/A | D29: 0 | E29: =_xlfn.XLOOKUP(A29,GOLD_ETFs!A:A,GOLD_ETFs!F:F) -> 83544112 | F29: =_xlfn.XLOOKUP(A29,spread!A:A,spread!F:F) -> 51906.55 | G29: =_xlfn.XLOOKUP(A29,corr!A:A,corr!I:I) -> 2968.002 | H29: =F29/G29 -> 17.488718 | I29: =_xlfn.XLOOKUP(A29,corr!A:A,corr!E:E,,1) -> 2017.21 | J29: =(_xlfn.XLOOKUP(BTC_ETH_ETFs!A29,MetaPlanet_BTC!A:A,MetaPlanet_BTC!C:C)*F29)/ 1000000 -> #N/A | K29: =B29+D29 -> 0 | L29: =SUM(K9:K28) -> 3910
A30: 45342 | B30: 135.6 | C30: #N/A | D30: 0 | E30: =_xlfn.XLOOKUP(A30,GOLD_ETFs!A:A,GOLD_ETFs!F:F) -> 83493304 | F30: =_xlfn.XLOOKUP(A30,spread!A:A,spread!F:F) -> 52037.65 | G30: =_xlfn.XLOOKUP(A30,corr!A:A,corr!I:I) -> 2988.52 | H30: =F30/G30 -> 17.412515 | I30: =_xlfn.XLOOKUP(A30,corr!A:A,corr!E:E,,1) -> 2024.41 | J30: =(_xlfn.XLOOKUP(BTC_ETH_ETFs!A30,MetaPlanet_BTC!A:A,MetaPlanet_BTC!C:C)*F30)/ 1000000 -> #N/A | K30: =B30+D30 -> 135.6 | L30: =SUM(K10:K29) -> 3997.4
A31: 45343 | B31: -35.6 | C31: #N/A | D31: 0 | E31: =_xlfn.XLOOKUP(A31,GOLD_ETFs!A:A,GOLD_ETFs!F:F) -> 83297784 | F31: =_xlfn.XLOOKUP(A31,spread!A:A,spread!F:F) -> 51388.56 | G31: =_xlfn.XLOOKUP(A31,corr!A:A,corr!I:I) -> 2927.677 | H31: =F31/G31 -> 17.552674 | I31: =_xlfn.XLOOKUP(A31,corr!A:A,corr!E:E,,1) -> 2025.99 | J31: =(_xlfn.XLOOKUP(BTC_ETH_ETFs!A31,MetaPlanet_BTC!A:A,MetaPlanet_BTC!C:C)*F31)/ 1000000 -> #N/A | K31: =B31+D31 -> -35.6 | L31: =SUM(K11:K30) -> 4239.1
A32: 45344 | B32: 251.4 | C32: #N/A | D32: 0 | E32: =_xlfn.XLOOKUP(A32,GOLD_ETFs!A:A,GOLD_ETFs!F:F) -> 83248856 | F32: =_xlfn.XLOOKUP(A32,spread!A:A,spread!F:F) -> 51650.63 | G32: =_xlfn.XLOOKUP(A32,corr!A:A,corr!I:I) -> 2984.752 | H32: =F32/G32 -> 17.304831 | I32: =_xlfn.XLOOKUP(A32,corr!A:A,corr!E:E,,1) -> 2024.39 | J32: =(_xlfn.XLOOKUP(BTC_ETH_ETFs!A32,MetaPlanet_BTC!A:A,MetaPlanet_BTC!C:C)*F32)/ 1000000 -> #N/A | K32: =B32+D32 -> 251.4 | L32: =SUM(K12:K31) -> 4361.8
A33: 45345 | B33: 232.5 | C33: #N/A | D33: 0 | E33: =_xlfn.XLOOKUP(A33,GOLD_ETFs!A:A,GOLD_ETFs!F:F) -> 83122120 | F33: =_xlfn.XLOOKUP(A33,spread!A:A,spread!F:F) -> 50981.2 | G33: =_xlfn.XLOOKUP(A33,corr!A:A,corr!I:I) -> 2942.478 | H33: =F33/G33 -> 17.325941 | I33: =_xlfn.XLOOKUP(A33,corr!A:A,corr!E:E,,1) -> 2035.4 | J33: =(_xlfn.XLOOKUP(BTC_ETH_ETFs!A33,MetaPlanet_BTC!A:A,MetaPlanet_BTC!C:C)*F33)/ 1000000 -> #N/A | K33: =B33+D33 -> 232.5 | L33: =SUM(K13:K32) -> 4693
... A57: 45379 | B57: 182.8 | C57: #N/A | D57: 0 | E57: =_xlfn.XLOOKUP(A57,GOLD_ETFs!A:A,GOLD_ETFs!F:F) -> 82716368 | F57: =_xlfn.XLOOKUP(A57,spread!A:A,spread!F:F) -> 70712.89 | G57: =_xlfn.XLOOKUP(A57,corr!A:A,corr!I:I) -> 3562.545 | H57: =F57/G57 -> 19.848982 | I57: =_xlfn.XLOOKUP(A57,corr!A:A,corr!E:E,,1) -> 2229.87 | J57: =(_xlfn.XLOOKUP(BTC_ETH_ETFs!A57,MetaPlanet_BTC!A:A,MetaPlanet_BTC!C:C)*F57)/ 1000000 -> #N/A | K57: =B57+D57 -> 182.8 | L57: =SUM(K37:K56) -> 5991.1
A58: 45380 | B58: 0 | C58: #N/A | D58: 0 | E58: =_xlfn.XLOOKUP(A58,GOLD_ETFs!A:A,GOLD_ETFs!F:F) -> 82714832 | F58: =_xlfn.XLOOKUP(A58,spread!A:A,spread!F:F) -> 69654.16 | G58: =_xlfn.XLOOKUP(A58,corr!A:A,corr!I:I) -> 3498.177 | H58: =F58/G58 -> 19.91156 | I58: 2229.87 | J58: =(_xlfn.XLOOKUP(BTC_ETH_ETFs!A58,MetaPlanet_BTC!A:A,MetaPlanet_BTC!C:C)*F58)/ 1000000 -> #N/A | K58: =B58+D58 -> 0 | L58: =SUM(K38:K57) -> 6081.6
A59: 45383 | B59: -85.7 | C59: #N/A | D59: 0 | E59: =_xlfn.XLOOKUP(A59,GOLD_ETFs!A:A,GOLD_ETFs!F:F) -> 82708176 | F59: =_xlfn.XLOOKUP(A59,spread!A:A,spread!F:F) -> 69767.89 | G59: =_xlfn.XLOOKUP(A59,corr!A:A,corr!I:I) -> 3497.45 | H59: =F59/G59 -> 19.948217 | I59: =_xlfn.XLOOKUP(A59,corr!A:A,corr!E:E,,1) -> 2251.44 | J59: =(_xlfn.XLOOKUP(BTC_ETH_ETFs!A59,MetaPlanet_BTC!A:A,MetaPlanet_BTC!C:C)*F59)/ 1000000 -> #N/A | K59: =B59+D59 -> -85.7 | L59: =SUM(K39:K58) -> 6221.2
A60: 45384 | B60: 39.5 | C60: #N/A | D60: 0 | E60: =_xlfn.XLOOKUP(A60,GOLD_ETFs!A:A,GOLD_ETFs!F:F) -> 82590392 | F60: =_xlfn.XLOOKUP(A60,spread!A:A,spread!F:F) -> 65702.14 | G60: =_xlfn.XLOOKUP(A60,corr!A:A,corr!I:I) -> 3271.837 | H60: =F60/G60 -> 20.081117 | I60: =_xlfn.XLOOKUP(A60,corr!A:A,corr!E:E,,1) -> 2280.67 | J60: =(_xlfn.XLOOKUP(BTC_ETH_ETFs!A60,MetaPlanet_BTC!A:A,MetaPlanet_BTC!C:C)*F60)/ 1000000 -> #N/A | K60: =B60+D60 -> 39.5 | L60: =SUM(K40:K59) -> 5572.8
A61: 45385 | B61: 113.5 | C61: #N/A | D61: 0 | E61: =_xlfn.XLOOKUP(A61,GOLD_ETFs!A:A,GOLD_ETFs!F:F) -> 82669000 | F61: =_xlfn.XLOOKUP(A61,spread!A:A,spread!F:F) -> 65742.2 | G61: =_xlfn.XLOOKUP(A61,corr!A:A,corr!I:I) -> 3307.371 | H61: =F61/G61 -> 19.87748 | I61: =_xlfn.XLOOKUP(A61,corr!A:A,corr!E:E,,1) -> 2300 | J61: =(_xlfn.XLOOKUP(BTC_ETH_ETFs!A61,MetaPlanet_BTC!A:A,MetaPlanet_BTC!C:C)*F61)/ 1000000 -> #N/A | K61: =B61+D61 -> 113.5 | L61: =SUM(K41:K60) -> 4964
A62: 45386 | B62: 213.4 | C62: #N/A | D62: 0 | E62: =_xlfn.XLOOKUP(A62,GOLD_ETFs!A:A,GOLD_ETFs!F:F) -> 82706488 | F62: =_xlfn.XLOOKUP(A62,spread!A:A,spread!F:F) -> 67948.37 | G62: =_xlfn.XLOOKUP(A62,corr!A:A,corr!I:I) -> 3326.073 | H62: =F62/G62 -> 20.429007 | I62: =_xlfn.XLOOKUP(A62,corr!A:A,corr!E:E,,1) -> 2290.94 | J62: =(_xlfn.XLOOKUP(BTC_ETH_ETFs!A62,MetaPlanet_BTC!A:A,MetaPlanet_BTC!C:C)*F62)/ 1000000 -> #N/A | K62: =B62+D62 -> 213.4 | L62: =SUM(K42:K61) -> 4745.5
A63: 45387 | B63: 203 | C63: #N/A | D63: 0 | E63: =_xlfn.XLOOKUP(A63,GOLD_ETFs!A:A,GOLD_ETFs!F:F) -> 82759216 | F63: =_xlfn.XLOOKUP(A63,spread!A:A,spread!F:F) -> 67660.41 | G63: =_xlfn.XLOOKUP(A63,corr!A:A,corr!I:I) -> 3335.583 | H63: =F63/G63 -> 20.284433 | I63: =_xlfn.XLOOKUP(A63,corr!A:A,corr!E:E,,1) -> 2329.75 | J63: =(_xlfn.XLOOKUP(BTC_ETH_ETFs!A63,MetaPlanet_BTC!A:A,MetaPlanet_BTC!C:C)*F63)/ 1000000 -> #N/A | K63: =B63+D63 -> 203 | L63: =SUM(K43:K62) -> 4486.4
A64: 45390 | B64: -223.8 | C64: #N/A | D64: 0 | E64: =_xlfn.XLOOKUP(A64,GOLD_ETFs!A:A,GOLD_ETFs!F:F) -> 82460168 | F64: =_xlfn.XLOOKUP(A64,spread!A:A,spread!F:F) -> 71706.37 | G64: =_xlfn.XLOOKUP(A64,corr!A:A,corr!I:I) -> 3689.258 | H64: =F64/G64 -> 19.436529 | I64: =_xlfn.XLOOKUP(A64,corr!A:A,corr!E:E,,1) -> 2339.03 | J64: =(_xlfn.XLOOKUP(BTC_ETH_ETFs!A64,MetaPlanet_BTC!A:A,MetaPlanet_BTC!C:C)*F64)/ 1000000 -> 0 | K64: =B64+D64 -> -223.8 | L64: =SUM(K44:K63) -> 4466.4
A65: 45391 | B65: -19.4 | C65: #N/A | D65: 0 | E65: =_xlfn.XLOOKUP(A65,GOLD_ETFs!A:A,GOLD_ETFs!F:F) -> 82450072 | F65: =_xlfn.XLOOKUP(A65,spread!A:A,spread!F:F) -> 69127.2 | G65: =_xlfn.XLOOKUP(A65,corr!A:A,corr!I:I) -> 3512.871 | H65: =F65/G65 -> 19.678263 | I65: =_xlfn.XLOOKUP(A65,corr!A:A,corr!E:E,,1) -> 2352.78 | J65: =(_xlfn.XLOOKUP(BTC_ETH_ETFs!A65,MetaPlanet_BTC!A:A,MetaPlanet_BTC!C:C)*F65)/ 1000000 -> #N/A | K65: =B65+D65 -> -19.4 | L65: =SUM(K45:K64) -> 2915.2
A66: 45392 | B66: 123.7 | C66: #N/A | D66: 0 | E66: =_xlfn.XLOOKUP(A66,GOLD_ETFs!A:A,GOLD_ETFs!F:F) -> 82276352 | F66: =_xlfn.XLOOKUP(A66,spread!A:A,spread!F:F) -> 69807.51 | G66: =_xlfn.XLOOKUP(A66,corr!A:A,corr!I:I) -> 3513.627 | H66: =F66/G66 -> 19.86765 | I66: =_xlfn.XLOOKUP(A66,corr!A:A,corr!E:E,,1) -> 2334.04 | J66: =(_xlfn.XLOOKUP(BTC_ETH_ETFs!A66,MetaPlanet_BTC!A:A,MetaPlanet_BTC!C:C)*F66)/ 1000000 -> #N/A | K66: =B66+D66 -> 123.7 | L66: =SUM(K46:K65) -> 1850.8
A67: 45393 | B67: 91.3 | C67: #N/A | D67: 0 | E67: =_xlfn.XLOOKUP(A67,GOLD_ETFs!A:A,GOLD_ETFs!F:F) -> 82207176 | F67: =_xlfn.XLOOKUP(A67,spread!A:A,spread!F:F) -> 70509.59 | G67: =_xlfn.XLOOKUP(A67,corr!A:A,corr!I:I) -> 3524.621 | H67: =F67/G67 -> 20.004871 | I67: =_xlfn.XLOOKUP(A67,corr!A:A,corr!E:E,,1) -> 2372.52 | J67: =(_xlfn.XLOOKUP(BTC_ETH_ETFs!A67,MetaPlanet_BTC!A:A,MetaPlanet_BTC!C:C)*F67)/ 1000000 -> #N/A | K67: =B67+D67 -> 91.3 | L67: =SUM(K47:K66) -> 1290.8
A68: 45394 | B68: -55.1 | C68: #N/A | D68: 0 | E68: =_xlfn.XLOOKUP(A68,GOLD_ETFs!A:A,GOLD_ETFs!F:F) -> 82268712 | F68: =_xlfn.XLOOKUP(A68,spread!A:A,spread!F:F) -> 67127.64 | G68: =_xlfn.XLOOKUP(A68,corr!A:A,corr!I:I) -> 3227.097 | H68: =F68/G68 -> 20.801246 | I68: =_xlfn.XLOOKUP(A68,corr!A:A,corr!E:E,,1) -> 2344.37 | J68: =(_xlfn.XLOOKUP(BTC_ETH_ETFs!A68,MetaPlanet_BTC!A:A,MetaPlanet_BTC!C:C)*F68)/ 1000000 -> #N/A | K68: =B68+D68 -> -55.1 | L68: =SUM(K48:K67) -> 1249.4
A69: 45397 | B69: -36.7 | C69: #N/A | D69: 0 | E69: =_xlfn.XLOOKUP(A69,GOLD_ETFs!A:A,GOLD_ETFs!F:F) -> 82031768 | F69: =_xlfn.XLOOKUP(A69,spread!A:A,spread!F:F) -> 63152.49 | G69: =_xlfn.XLOOKUP(A69,corr!A:A,corr!I:I) -> 3083.275 | H69: =F69/G69 -> 20.482276 | I69: =_xlfn.XLOOKUP(A69,corr!A:A,corr!E:E,,1) -> 2383.34 | J69: =(_xlfn.XLOOKUP(BTC_ETH_ETFs!A69,MetaPlanet_BTC!A:A,MetaPlanet_BTC!C:C)*F69)/ 1000000 -> #N/A | K69: =B69+D69 -> -36.7 | L69: =SUM(K49:K68) -> 995.5
A70: 45398 | B70: -58 | C70: #N/A | D70: 0 | E70: =_xlfn.XLOOKUP(A70,GOLD_ETFs!A:A,GOLD_ETFs!F:F) -> 81945304 | F70: =_xlfn.XLOOKUP(A70,spread!A:A,spread!F:F) -> 63039.97 | G70: =_xlfn.XLOOKUP(A70,corr!A:A,corr!I:I) -> 3071.163 | H70: =F70/G70 -> 20.526416 | I70: =_xlfn.XLOOKUP(A70,corr!A:A,corr!E:E,,1) -> 2382.89 | J70: =(_xlfn.XLOOKUP(BTC_ETH_ETFs!A70,MetaPlanet_BTC!A:A,MetaPlanet_BTC!C:C)*F70)/ 1000000 -> #N/A | K70: =B70+D70 -> -58 | L70: =SUM(K50:K69) -> 1113.1
...

Sheet BTC_Drawdown
A1: Date | B1: snapped_at.2 | C1: BTC Spot | D1: market_cap | E1: total_volume
A2: 41392 | B2: 00:00:00 UTC | C2: 135.3 | D2: 1500517590 | E2: 0
A3: 41393 | B3: 00:00:00 UTC | C3: 141.96 | D3: 1575032004 | E3: 0
A4: 41394 | B4: 00:00:00 UTC | C4: 135.3 | D4: 1501657493 | E4: 0
A5: 41395 | B5: 00:00:00 UTC | C5: 117 | D5: 1298951550 | E5: 0
A6: 41396 | B6: 00:00:00 UTC | C6: 103.43 | D6: 1148667722 | E6: 0
A7: 41397 | B7: 00:00:00 UTC | C7: 91.01 | D7: 1011066494 | E7: 0
A8: 41398 | B8: 00:00:00 UTC | C8: 111.25 | D8: 1236351844 | E8: 0
A9: 41399 | B9: 00:00:00 UTC | C9: 116.79 | D9: 1298377788 | E9: 0
A10: 41400 | B10: 00:00:00 UTC | C10: 118.33 | D10: 1315992304 | E10: 0
A11: 41401 | B11: 00:00:00 UTC | C11: 106.4 | D11: 1183766500 | E11: 0
A12: 41402 | B12: 00:00:00 UTC | C12: 112.64 | D12: 1253655040 | E12: 0
A13: 41403 | B13: 00:00:00 UTC | C13: 113 | D13: 1258130700 | E13: 0
... A4667: 46059 | B4667: 00:00:00 UTC | C4667: 62853.69 | D4667: 1262033077145 | E4667: 142403234254

Sheet MetaPlanet_BTC
A1: x | B1: y | C1: MetaPlanet Purchases (in BTC)
A2: 45390 | B2: 0
A3: 45405 | B3: 97.85 | C3: =B3-B2 -> 97.85
A4: 45406 | B4: 97.85 | C4: =B4-B3 -> 0
A5: 45407 | B5: 97.85 | C5: =B5-B4 -> 0
A6: 45408 | B6: 97.85 | C6: =B6-B5 -> 0
A7: 45409 | B7: 97.85 | C7: =B7-B6 -> 0
A8: 45410 | B8: 97.85 | C8: =B8-B7 -> 0
A9: 45411 | B9: 97.85 | C9: =B9-B8 -> 0
A10: 45412 | B10: 97.85 | C10: =B10-B9 -> 0
A11: 45413 | B11: 97.85 | C11: =B11-B10 -> 0
A12: 45414 | B12: 97.85 | C12: =B12-B11 -> 0
A13: 45415 | B13: 97.85 | C13: =B13-B12 -> 0
A14: 45416 | B14: 97.85 | C14: =B14-B13 -> 0
... A641: 46043 | B641: 35102.005 | C641: =B641-B640 -> 0

Sheet Table1
A1: Date | B1: Reported.2 | C1: BTC Acq | D1: Avg BTC Cost | E1: Acq Cost ($M) | F1: BTC Holdings
A2: 08/10/2020 | B2: 00:00:00 | C2: ₿21,454 | D2: $11,652 | E2: $250 | F2: ₿21,454
A3: 9/14/2020 | C3: ₿16,796 | D3: $10,419 | E3: $175 | F3: ₿38,250
A4: 12/04/2020 | B4: 00:00:00 | C4: ₿2,574 | D4: $19,427 | E4: $50 | F4: ₿40,824
A5: 12/21/2020 | C5: ₿29,646 | D5: $21,925 | E5: $650 | F5: ₿70,470
A6: 1/22/2021 | C6: ₿314 | D6: $31,808 | E6: $10 | F6: ₿70,784
A7: 02/02/2021 | B7: 00:00:00 | C7: ₿295 | D7: $33,810 | E7: $10 | F7: ₿71,079
A8: 2/19/2021 | C8: ₿19,452 | D8: $52,765 | E8: $1,023 | F8: ₿90,531
A9: 03/01/2021 | B9: 00:00:00 | C9: ₿328 | D9: $45,710 | E9: $15 | F9: ₿90,859
A10: 03/05/2021 | B10: 00:00:00 | C10: ₿205 | D10: $48,888 | E10: $10 | F10: ₿91,064
A11: 03/12/2021 | B11: 00:00:00 | C11: ₿262 | D11: $57,146 | E11: $15 | F11: ₿91,326
A12: 04/05/2021 | B12: 00:00:00 | C12: ₿253 | D12: $59,339 | E12: $15 | F12: ₿91,579
A13: 5/13/2021 | C13: ₿271 | D13: $55,387 | E13: $15 | F13: ₿91,850
A14: 5/18/2021 | C14: ₿229 | D14: $43,663 | E14: $10 | F14: ₿92,079
A15: 6/21/2021 | C15: ₿13,005 | D15: $37,617 | E15: $489 | F15: ₿105,084
A16: 8/24/2021 | C16: ₿3,907 | D16: $45,294 | E16: $177 | F16: ₿108,991
A17: 9/13/2021 | C17: ₿5,050 | D17: $48,099 | E17: $242 | F17: ₿114,041
A18: 11/29/2021 | C18: ₿7,002 | D18: $59,187 | E18: $414 | F18: ₿121,043
A19: 12/09/2021 | B19: 00:00:00 | C19: ₿1,434 | D19: $57,477 | E19: $82 | F19: ₿122,477
A20: 12/30/2021 | C20: ₿1,914 | D20: $49,229 | E20: $94 | F20: ₿124,391
A21: 02/01/2022 | B21: 00:00:00 | C21: ₿660 | D21: $37,865 | E21: $25 | F21: ₿125,051
A22: 04/05/2022 | B22: 00:00:00 | C22: ₿4,167 | D22: $45,714 | E22: $190 | F22: ₿129,218
A23: 6/29/2022 | C23: ₿480 | D23: $20,817 | E23: $10 | F23: ₿129,698
A24: 9/20/2022 | C24: ₿301 | D24: $19,851 | E24: $6 | F24: ₿129,999
A25: 12/28/2022 | C25: ₿2,501 | D25: $17,847 | E25: $45 | F25: ₿132,500
A26: 3/23/2023 | C26: ₿6,455 | D26: $23,238 | E26: $150 | F26: ₿138,955
A27: 04/05/2023 | B27: 00:00:00 | C27: ₿1,045 | D27: $28,016 | E27: $29 | F27: ₿140,000
A28: 6/28/2023 | C28: ₿12,333 | D28: $28,136 | E28: $347 | F28: ₿152,333
A29: 08/01/2023 | B29: 00:00:00 | C29: ₿467 | D29: $30,788 | E29: $14 | F29: ₿152,800
A30: 9/25/2023 | C30: ₿5,445 | D30: $27,053 | E30: $147 | F30: ₿158,245
A31: 11/01/2023 | B31: 00:00:00 | C31: ₿155 | D31: $34,495 | E31: $5 | F31: ₿158,400
A32: 11/30/2023 | C32: ₿16,130 | D32: $36,785 | E32: $593 | F32: ₿174,530
A33: 12/27/2023 | C33: ₿14,620 | D33: $42,110 | E33: $616 | F33: ₿189,150
A34: 02/06/2024 | B34: 00:00:00 | C34: ₿850 | D34: $43,723 | E34: $37 | F34: ₿190,000
A35: 2/26/2024 | C35: ₿3,000 | D35: $51,813 | E35: $155 | F35: ₿193,000
A36: 03/11/2024 | B36: 00:00:00 | C36: ₿12,000 | D36: $68,477 | E36: $822 | F36: ₿205,000
A37: 3/19/2024 | C37: ₿9,245 | D37: $67,382 | E37: $623 | F37: ₿214,245
A38: 4/29/2024 | C38: ₿155 | D38: $63,397 | E38: $10 | F38: ₿214,400
A39: 6/20/2024 | C39: ₿11,931 | D39: $65,883 | E39: $786 | F39: ₿226,331
A40: 08/01/2024 | B40: 00:00:00 | C40: ₿169 | D40: $67,455 | E40: $11 | F40: ₿226,500
...

Sheet Sheet3
A1: Reported | B1: BTC Acq | C1: Avg BTC Cost | D1: Acq Cost ($M) | E1: BTC Holdings
A2: 44112 | B2: ₿21,454 | C2: $11,652 | D2: $250 | E2: ₿21,454
A3: 9/14/2020 | B3: ₿16,796 | C3: $10,419 | D3: $175 | E3: ₿38,250
A4: 43933 | B4: ₿2,574 | C4: $19,427 | D4: $50 | E4: ₿40,824
A5: 12/21/2020 | B5: ₿29,646 | C5: $21,925 | D5: $650 | E5: ₿70,470
A6: 1/22/2021 | B6: ₿314 | C6: $31,808 | D6: $10 | E6: ₿70,784
A7: 44229 | B7: ₿295 | C7: $33,810 | D7: $10 | E7: ₿71,079
A8: 2/19/2021 | B8: ₿19,452 | C8: $52,765 | D8: $1,023 | E8: ₿90,531
A9: 44199 | B9: ₿328 | C9: $45,710 | D9: $15 | E9: ₿90,859
A10: 44319 | B10: ₿205 | C10: $48,888 | D10: $10 | E10: ₿91,064
A11: 44533 | B11: ₿262 | C11: $57,146 | D11: $15 | E11: ₿91,326
A12: 44320 | B12: ₿253 | C12: $59,339 | D12: $15 | E12: ₿91,579
A13: 5/13/2021 | B13: ₿271 | C13: $55,387 | D13: $15 | E13: ₿91,850
A14: 5/18/2021 | B14: ₿229 | C14: $43,663 | D14: $10 | E14: ₿92,079
A15: 6/21/2021 | B15: ₿13,005 | C15: $37,617 | D15: $489 | E15: ₿105,084
A16: 8/24/2021 | B16: ₿3,907 | C16: $45,294 | D16: $177 | E16: ₿108,991
A17: 9/13/2021 | B17: ₿5,050 | C17: $48,099 | D17: $242 | E17: ₿114,041
A18: 11/29/2021 | B18: ₿7,002 | C18: $59,187 | D18: $414 | E18: ₿121,043
A19: 44451 | B19: ₿1,434 | C19: $57,477 | D19: $82 | E19: ₿122,477
A20: 12/30/2021 | B20: ₿1,914 | C20: $49,229 | D20: $94 | E20: ₿124,391
A21: 44563 | B21: ₿660 | C21: $37,865 | D21: $25 | E21: ₿125,051
A22: 44685 | B22: ₿4,167 | C22: $45,714 | D22: $190 | E22: ₿129,218
A23: 6/29/2022 | B23: ₿480 | C23: $20,817 | D23: $10 | E23: ₿129,698
A24: 9/20/2022 | B24: ₿301 | C24: $19,851 | D24: $6 | E24: ₿129,999
A25: 12/28/2022 | B25: ₿2,501 | C25: $17,847 | D25: $45 | E25: ₿132,500
A26: 3/23/2023 | B26: ₿6,455 | C26: $23,238 | D26: $150 | E26: ₿138,955
A27: 45050 | B27: ₿1,045 | C27: $28,016 | D27: $29 | E27: ₿140,000
A28: 6/28/2023 | B28: ₿12,333 | C28: $28,136 | D28: $347 | E28: ₿152,333
A29: 44934 | B29: ₿467 | C29: $30,788 | D29: $14 | E29: ₿152,800
A30: 9/25/2023 | B30: ₿5,445 | C30: $27,053 | D30: $147 | E30: ₿158,245
A31: 44937 | B31: ₿155 | C31: $34,495 | D31: $5 | E31: ₿158,400
A32: 11/30/2023 | B32: ₿16,130 | C32: $36,785 | D32: $593 | E32: ₿174,530
A33: 12/27/2023 | B33: ₿14,620 | C33: $42,110 | D33: $616 | E33: ₿189,150
A34: 45445 | B34: ₿850 | C34: $43,723 | D34: $37 | E34: ₿190,000
A35: 2/26/2024 | B35: ₿3,000 | C35: $51,813 | D35: $155 | E35: ₿193,000
A36: 45599 | B36: ₿12,000 | C36: $68,477 | D36: $822 | E36: ₿205,000
A37: 3/19/2024 | B37: ₿9,245 | C37: $67,382 | D37: $623 | E37: ₿214,245
A38: 4/29/2024 | B38: ₿155 | C38: $63,397 | D38: $10 | E38: ₿214,400
A39: 6/20/2024 | B39: ₿11,931 | C39: $65,883 | D39: $786 | E39: ₿226,331
A40: 45299 | B40: ₿169 | C40: $67,455 | D40: $11 | E40: ₿226,500
...

Sheet Sheet1
A1: Date | B1: Shanghai Gold Warrants
A2: 39793 | B2: 162
A3: 39794 | B3: 222
A4: 39797 | B4: 222
A5: 39798 | B5: 504
A6: 39799 | B6: 504
A7: 39800 | B7: 504
A8: 39801 | B8: 504
A9: 39804 | B9: 504
A10: 39805 | B10: 504
A11: 39806 | B11: 504
A12: 39807 | B12: 24
A13: 39808 | B13: 24
... A4098: 45965 | B4098: 87816

Sheet cny_bond
A1: Date | B1: USDCNY | C1: USDCNH | D1: CNYUSD | E1: CNHUSD | F1: BTC Spot | G1: US 2Y Minus China 2Y
A2: 40182 | B2: 6.8273 | D2: 0.14648 | G2: 2.75165
A3: 40183 | B3: 6.8272 | D3: 0.14647 | G3: 2.75285
A4: 40184 | B4: 6.8274 | D4: 0.14647 | G4: 2.82947
A5: 40185 | B5: 6.8275 | D5: 0.14646 | G5: 2.79955
A6: 40186 | B6: 6.8276 | D6: 0.14646 | G6: 2.85384
A7: 40189 | B7: 6.8263 | D7: 0.14646 | G7: 2.88237
A8: 40190 | B8: 6.8271 | D8: 0.14648 | G8: 2.80739
A9: 40191 | B9: 6.8267 | D9: 0.14647 | G9: 2.83117
A10: 40192 | B10: 6.8272 | D10: 0.14648 | G10: 2.81892
A11: 40193 | B11: 6.827 | D11: 0.14648 | G11: 2.81229
A12: 40196 | B12: 6.8269 | D12: 0.14649 | G12: 2.81229
A13: 40197 | B13: 6.8277 | D13: 0.14647 | G13: 2.80569
... A31: 40221 | B31: 6.8334 | D31: 0.14634 | G31: 2.86625
A32: 40224 | D32: 0.14648 | G32: 2.86625
A33: 40225 | D33: 0.14637 | G33: 2.8547
A34: 40226 | D34: 0.1465 | G34: 2.8881
A35: 40227 | D35: 0.14647 | G35: 2.87752
A36: 40228 | D36: 0.14641 | G36: 2.85692
A37: 40231 | B37: 6.8265 | D37: 0.14649 | G37: 2.91244
A38: 40232 | B38: 6.8265 | D38: 0.14646 | G38: 2.85739
A39: 40233 | B39: 6.827 | D39: 0.14648 | G39: 2.83176
A40: 40234 | B40: 6.8268 | D40: 0.14649 | G40: 2.81274
A41: 40235 | B41: 6.8261 | D41: 0.1465 | G41: 2.79991
A42: 40238 | B42: 6.8263 | D42: 0.1465 | G42: 2.81204
A43: 40239 | B43: 6.8266 | D43: 0.14648 | G43: 2.81629
A44: 40240 | B44: 6.8258 | D44: 0.1465 | G44: 2.81371
A45: 40241 | B45: 6.8265 | D45: 0.14649 | G45: 2.7511
A46: 40242 | B46: 6.8265 | D46: 0.14649 | G46: 2.78868
A47: 40245 | B47: 6.8264 | D47: 0.14649 | G47: 2.82475
A48: 40246 | B48: 6.8264 | D48: 0.1465 | G48: 2.83355
... A66: 40270 | B66: 6.8257 | D66: 0.14651 | G66: 2.8127
A67: 40273 | D67: 0.14651 | G67: 2.81783
A68: 40274 | B68: 6.8258 | D68: 0.1465 | G68: 2.81457
A69: 40275 | B69: 6.8254 | D69: 0.1465 | G69: 2.8051
A70: 40276 | B70: 6.8243 | D70: 0.14653 | G70: 2.82601
A71: 40277 | B71: 6.8236 | D71: 0.14654 | G71: 2.82618
A72: 40280 | B72: 6.8258 | D72: 0.14651 | G72: 2.8095
A73: 40281 | B73: 6.8256 | D73: 0.1465 | G73: 2.77202
A74: 40282 | B74: 6.8258 | D74: 0.1465 | G74: 2.81084
...

Sheet yield_decomp
A1: Date | B1: 10Y Real Yield | C1: 10Y Breakeven Inflation | D1: 10Y Nominal Yield | E1: Nominal Yield Minus Real Yield Spread | F1: San Francisco Term Premium
A2: 45372 | B2: 1.93 | C2: 2.3549 | D2: 4.2669 | E2: 2.3369 | F2: =_xlfn.XLOOKUP(A2,[1]FRBSF_term_premium!A:A,[1]FRBSF_term_premium!D:D) -> 0.828095
A3: 45373 | B3: 1.87 | C3: 2.3477 | D3: 4.1981 | E3: 2.3281 | F3: =_xlfn.XLOOKUP(A3,[1]FRBSF_term_premium!A:A,[1]FRBSF_term_premium!D:D) -> 0.804067
A4: 45376 | B4: 1.92 | C4: 2.3363 | D4: 4.2454 | E4: 2.3254 | F4: =_xlfn.XLOOKUP(A4,[1]FRBSF_term_premium!A:A,[1]FRBSF_term_premium!D:D) -> 0.841934
A5: 45377 | B5: 1.92 | C5: 2.3287 | D5: 4.2316 | E5: 2.3116 | F5: =_xlfn.XLOOKUP(A5,[1]FRBSF_term_premium!A:A,[1]FRBSF_term_premium!D:D) -> 0.816905
A6: 45378 | B6: 1.88 | C6: 2.3086 | D6: 4.1903 | E6: 2.3103 | F6: =_xlfn.XLOOKUP(A6,[1]FRBSF_term_premium!A:A,[1]FRBSF_term_premium!D:D) -> 0.789819
A7: 45379 | B7: 1.88 | C7: 2.3246 | D7: 4.2003 | E7: 2.3203 | F7: =_xlfn.XLOOKUP(A7,[1]FRBSF_term_premium!A:A,[1]FRBSF_term_premium!D:D) -> 0.757235
A8: 45383 | B8: 1.98 | C8: 2.3462 | D8: 4.3092 | E8: 2.3292 | F8: =_xlfn.XLOOKUP(A8,[1]FRBSF_term_premium!A:A,[1]FRBSF_term_premium!D:D) -> 0.822846
A9: 45384 | B9: 2 | C9: 2.3646 | D9: 4.3491 | E9: 2.3491 | F9: =_xlfn.XLOOKUP(A9,[1]FRBSF_term_premium!A:A,[1]FRBSF_term_premium!D:D) -> 0.865329
A10: 45385 | B10: 2 | C10: 2.3519 | D10: 4.3472 | E10: 2.3472 | F10: =_xlfn.XLOOKUP(A10,[1]FRBSF_term_premium!A:A,[1]FRBSF_term_premium!D:D) -> 0.871042
A11: 45386 | B11: 1.97 | C11: 2.3622 | D11: 4.3094 | E11: 2.3394 | F11: =_xlfn.XLOOKUP(A11,[1]FRBSF_term_premium!A:A,[1]FRBSF_term_premium!D:D) -> 0.825577
A12: 45387 | B12: 2.02 | C12: 2.3738 | D12: 4.4016 | E12: 2.3816 | F12: =_xlfn.XLOOKUP(A12,[1]FRBSF_term_premium!A:A,[1]FRBSF_term_premium!D:D) -> 0.851266
A13: 45390 | B13: 2.04 | C13: 2.3911 | D13: 4.4198 | E13: 2.3798 | F13: =_xlfn.XLOOKUP(A13,[1]FRBSF_term_premium!A:A,[1]FRBSF_term_premium!D:D) -> 0.851739
... A291: 45796 | B291: 2.1 | C291: 2.3597 | D291: 4.4474 | E291: 2.3474 | F291: =_xlfn.XLOOKUP(A291,[1]FRBSF_term_premium!A:A,[1]FRBSF_term_premium!D:D) -> 1.307942
A292: 45797 | B292: 2.13 | C292: 2.3584 | D292: 4.4869 | E292: 2.3569
A293: 45798 | B293: 2.23 | C293: 2.3643 | D293: 4.5985 | E293: 2.3685
A294: 45799 | B294: 2.2 | C294: 2.3629 | D294: 4.5287 | E294: 2.3287
A295: 45800 | B295: 2.18 | C295: 2.3464 | D295: 4.511 | E295: 2.331
A296: 45804 | B296: 2.11 | C296: 2.3378 | D296: 4.4436 | E296: 2.3336
A297: 45805 | B297: 2.15 | C297: 2.3415 | D297: 4.4773 | E297: 2.3273
A298: 45806 | B298: 2.11 | C298: 2.3328 | D298: 4.418 | E298: 2.308
A299: 45807 | B299: 2.07 | C299: 2.3297 | D299: 4.4004 | E299: 2.3304
A300: 45810 | B300: 2.13 | C300: 2.3471 | D300: 4.4399 | E300: 2.3099
A301: 45811 | B301: 2.14 | C301: 2.3487 | D301: 4.4537 | E301: 2.3137
A302: 45812 | B302: 2.06 | C302: 2.3091 | D302: 4.3552 | E302: 2.2952
A303: 45813 | B303: 2.11 | C303: 2.2936 | D303: 4.3906 | E303: 2.2806
A304: 45814 | B304: 2.2 | C304: 2.3174 | D304: 4.5056 | E304: 2.3056
A305: 45815 | E305: 2.3056
A306: 45816 | E306: 2.3056
A307: 45817 | B307: 2.18 | C307: 2.313 | D307: 4.4738 | E307: 2.2938
A308: 45818 | B308: 2.18 | C308: 2.3036 | D308: 4.4698 | E308: 2.2898
A309: 45819 | B309: 2.14 | C309: 2.2869 | D309: 4.4203 | E309: 2.2803
A310: 45820 | B310: 2.11 | C310: 2.269 | D310: 4.3592 | E310: 2.2492
A311: 45821 | B311: 2.13 | C311: 2.2893 | D311: 4.3987 | E311: 2.2687
A312: 45822 | E312: 2.2687
A313: 45823 | E313: 2.2687
A314: 45824 | B314: 2.16 | C314: 2.3118 | D314: 4.4462 | E314: 2.2862
A315: 45825 | B315: 2.08 | C315: 2.3233 | D315: 4.3888 | E315: 2.3088
A316: 45826 | B316: 2.07 | C316: 2.323 | D316: 4.3909 | E316: 2.3209
A317: 45828 | B317: 2.05 | C317: 2.341 | D317: 4.3751 | E317: 2.3251
...

Sheet Sheet5
A1: Date | B1: kimwtp10 Term Premium
A2: 40182 | B2: 1.1325
A3: 40183 | B3: 1.1012
A4: 40184 | B4: 1.1205
A5: 40185 | B5: 1.13
A6: 40186 | B6: 1.1216
A7: 40189 | B7: 1.1267
A8: 40190 | B8: 1.0869
A9: 40191 | B9: 1.1029
A10: 40192 | B10: 1.0861
A11: 40193 | B11: 1.0601
A12: 40197 | B12: 1.0657
A13: 40198 | B13: 1.0485
... A3909: 45891 | B3909: 0.4935
A3910: 45894
A3911: 45895
A3912: 45896

Sheet SPX_selloff
A1: Date | B1: SPX
A2: 10595 | B2: 24.81
A3: 10596 | B3: 24.86
A4: 10597 | B4: 24.85
A5: 10600 | B5: 24.25
A6: 10601 | B6: 24.17
A7: 10602 | B7: 24.54
A8: 10603 | B8: 24.58
A9: 10604 | B9: 24.54
A10: 10607 | B10: 24.59
A11: 10608 | B11: 24.23
A12: 10609 | B12: 24.56
A13: 10610 | B13: 24.69
... A24300: 45924 | B24300: 6637.97

Sheet M2
A1: Date | B1: M2 | C1: BTC Spot
A2: 40210 | B2: 4.7184902e+13
A3: 40211 | B3: 4.7252125e+13
A4: 40212 | B4: 4.7133872e+13
A5: 40213 | B5: 4.7115257e+13
A6: 40214 | B6: 4.7040066e+13
A7: 40217 | B7: 4.7052588e+13
A8: 40218 | B8: 4.7192579e+13
A9: 40219 | B9: 4.7107984e+13
A10: 40220 | B10: 4.71277e+13
A11: 40221 | B11: 4.7055676e+13
A12: 40224 | B12: 4.7063779e+13
A13: 40225 | B13: 4.7235136e+13
... A133: 40390 | B133: 4.8352649e+13
A134: 40392 | B134: 4.8548826e+13 | C134: 0.06
A135: 40393 | B135: 4.867235e+13 | C135: 0.06
A136: 40394 | B136: 4.8567863e+13 | C136: 0.06
A137: 40395 | B137: 4.8647398e+13 | C137: 0.06
